Workbook

Sheet SETTINGS
A2: Republic of the Philippines
A3: DON HONORIO VENTURA TECHNOLOGICAL STATE UNIVERSITY
A4: STO. TOMAS CAMPUS
A5: Moras dela Paz, Sto. Tomas, Pampanga
A7: GRADING SHEET SETTINGS
A9: No. | B9: Student Number | C9: Name | E9: GRADING SHEET SETTINGS
A10: 1 | E10: Semster: | F10: Second Semester
A11: 2 | E11: Academic Year: | F11: A.Y. 2023-2024
A12: 3
A13: 4 | E13: Subject Description:
A14: 5 | E14: Subject Code:
A15: 6
A16: 7 | E16: Class Section:
A17: 8
A18: 9 | E18: PERCENTAGE
A19: 10
A20: 11 | E20: Laboratory
A21: 12 | E21: Attendace | F21: 0
A22: 13 | E22: Quizzes | F22: 0
A23: 14 | E23: Activities | F23: 0
A24: 15 | E24: Recitation | F24: 0
A25: 16 | E25: Laboratory | F25: 0
A26: 17 | E26: Major Exam | F26: 0 | G26: =SUM(F21:F26) -> 0
A27: 18 | E27: Non-Laboratory
A28: 19 | E28: Attendace | F28: 0
A29: 20 | E29: Quizzes | F29: 0
A30: 21 | E30: Activities | F30: 0
A31: 22 | E31: Recitation | F31: 0
A32: 23 | E32: Major Exam | F32: 0 | G32: =SUM(F28:F32) -> 0
A33: 24
A34: 25
A35: 26
A36: 27
A37: 28
A38: 29
A39: 30
A40: 31
A41: 32
A42: 33
A43: 34
...

Sheet ATT
D1: MIDTERM - MIDTERM - MIDTERM - MIDTERM - MIDTERM - MIDTERM - MIDTERM - MIDTERM - MIDTERM - | U1: FINALTERM - FINALTERM - FINALTERM - FINALTERM - FINALTERM - FINALTERM - FINALTERM - FINALTERM
B2: No. | C2: Student Name | D2: 44230 | G2: 46065 | I2: 46076 | S2: TOTAL | AJ2: TOTAL
B6: 1 | C6: =SETTINGS!C10 -> 0 | S6: =100-SUM(D6:R6) -> 100 | U6: 10 | AJ6: =S6-SUM(U6:AI6) -> 90
B7: 2 | C7: =SETTINGS!C11 -> 0 | S7: =100-SUM(D7:R7) -> 100 | AJ7: =S7-SUM(U7:AI7) -> 100
B8: 3 | C8: =SETTINGS!C12 -> 0 | S8: =100-SUM(D8:R8) -> 100 | AJ8: =S8-SUM(U8:AI8) -> 100
B9: 4 | C9: =SETTINGS!C13 -> 0 | S9: =100-SUM(D9:R9) -> 100 | AJ9: =S9-SUM(U9:AI9) -> 100
B10: 5 | C10: =SETTINGS!C14 -> 0 | S10: =100-SUM(D10:R10) -> 100 | AJ10: =S10-SUM(U10:AI10) -> 100
B11: 6 | C11: =SETTINGS!C15 -> 0 | S11: =100-SUM(D11:R11) -> 100 | AJ11: =S11-SUM(U11:AI11) -> 100
B12: 7 | C12: =SETTINGS!C16 -> 0 | S12: =100-SUM(D12:R12) -> 100 | AJ12: =S12-SUM(U12:AI12) -> 100
B13: 8 | C13: =SETTINGS!C17 -> 0 | S13: =100-SUM(D13:R13) -> 100 | AJ13: =S13-SUM(U13:AI13) -> 100
B14: 9 | C14: =SETTINGS!C18 -> 0 | S14: =100-SUM(D14:R14) -> 100 | AJ14: =S14-SUM(U14:AI14) -> 100
B15: 10 | C15: =SETTINGS!C19 -> 0 | S15: =100-SUM(D15:R15) -> 100 | AJ15: =S15-SUM(U15:AI15) -> 100
B16: 11 | C16: =SETTINGS!C20 -> 0 | S16: =100-SUM(D16:R16) -> 100 | AJ16: =S16-SUM(U16:AI16) -> 100
B17: 12 | C17: =SETTINGS!C21 -> 0 | S17: =100-SUM(D17:R17) -> 100 | AJ17: =S17-SUM(U17:AI17) -> 100
B18: 13 | C18: =SETTINGS!C22 -> 0 | S18: =100-SUM(D18:R18) -> 100 | AJ18: =S18-SUM(U18:AI18) -> 100
... B81: 76 | C81: =SETTINGS!C85 -> 0 | S81: =100-SUM(D81:R81) -> 100 | AJ81: =S81-SUM(U81:AI81) -> 100

Sheet MID-FINAL
E2: M I D T E R M ----- M I D T E R M ----- M I D T E R M ----- M I D T E R M -----M I D T E R M ----- M I D T E R M ----- M I D T E R M | AI2: F I N A L T E R M ----- F I N A L T E R M ----- F I N A L T E R M ----- F I N A L T E R M -----F I N A L T E R M ----- F I N A L T E R M ----- F I N A L T E R M
B3: No. | C3: Student Name | D3: Classification | E3: Quizzes | M3: Activity | U3: Attendance | W3: Recitation | Y3: Laboratory | AA3: Laboratory | AD3: Major Exam | AG3: MIDTERM GRADE | AI3: Quizzes | AQ3: Activity | AY3: Attendance | BA3: Recitation | BC3: Laboratory | BF3: Major Exam | BI3: FINAL TERM GRADE
E4: 11-11 | F4: 11-11 | G4: 11-11 | H4: 11-11 | I4: 11-11 | J4: Total Raw Score | K4: Equiv. | L4: Percentage | M4: 11-11 | N4: 11-11 | O4: 11-11 | P4: 11-11 | Q4: 11-11 | R4: Total Raw Score | S4: Equiv. | T4: Percentage | U4: Raw Score | V4: Percentage | W4: 100 | X4: Percentage | Y4: 100 | Z4: Percentage | AA4: 11-11 | AB4: Transmuted Grades | AC4: Percentage | AD4: 11-11 | AE4: Transmuted Grades | AF4: Percentage | AI4: 11-11 | AJ4: 11-11 | AK4: 11-11 | AL4: 11-11 | AM4: 11-11 | AN4: Total Raw Score | AO4: Equiv. | AP4: Percentage | AQ4: 11-11 | AR4: 11-11 | AS4: 11-11 | AT4: 11-11 | AU4: 11-11 | AV4: Total Raw Score | AW4: Equiv. | AX4: Percentage | AY4: Raw Score | AZ4: Percentage | BA4: 100 | BB4: Percentage | BC4: 11-11 | BD4: Transmuted Grades | BE4: Percentage | BF4: 11-11 | BG4: Transmuted Grades | BH4: Percentage
E5: Q1 | F5: Q2 | G5: Q3 | H5: Q4 | I5: Q5 | M5: A1 | N5: A2 | O5: A3 | P5: A4 | Q5: A5 | AA5: Raw Score | AD5: Raw Score | AI5: Q1 | AJ5: Q2 | AK5: Q3 | AL5: Q4 | AM5: Q5 | AQ5: A1 | AR5: A2 | AS5: A3 | AT5: A4 | AU5: A5 | BC5: Raw Score | BF5: Raw Score
E6: 10 | F6: 0 | G6: 0 | H6: 0 | I6: 0 | J6: =SUM(E6:I6) -> 10 | K6: =J6/$J$6*50+50 -> 100 | M6: 10 | N6: 0 | O6: 0 | P6: 0 | Q6: 0 | R6: =SUM(M6:Q6) -> 10 | S6: =R6/$R$6*50+50 -> 100 | U6: 100 | AA6: 30 | AB6: =AA6/$AA$6*50+50 -> 100 | AD6: 30 | AE6: =AD6/$AD$6*50+50 -> 100 | AI6: 10 | AJ6: 0 | AK6: 0 | AL6: 0 | AM6: 0 | AN6: =SUM(AI6:AM6) -> 10 | AO6: =AN6/$AN$6*50+50 -> 100 | AQ6: 10 | AR6: 0 | AS6: 0 | AT6: 0 | AU6: 0 | AV6: =SUM(AQ6:AU6) -> 10 | AW6: =AV6/$AV$6*50+50 -> 100 | AY6: 100 | BC6: 100 | BD6: =BC6/$BC$6*50+50 -> 100 | BF6: 100 | BG6: =BF6/$BF$6*50+50 -> 100
B7: 1 | C7: =SETTINGS!C10 -> 0 | D7: Non-Lab | J7: =SUM(E7:I7) -> 0 | K7: =J7/$J$6*50+50 -> 50 | L7: =K7*(0.01*IF(D7="lab",SETTINGS!$F$22,SETTINGS!$F$29)) -> 0 | R7: =SUM(M7:Q7) -> 0 | S7: =R7/$R$6*50+50 -> 50 | T7: =S7*(0.01*IF(D7="lab",SETTINGS!$F$23,SETTINGS!$F$30)) -> 0 | U7: =ATT!S6 -> 100 | V7: =U7*(0.01*IF(D7="lab",SETTINGS!$F$21,SETTINGS!$F$28)) -> 0 | W7: 100 | X7: =W7*(0.01*IF(D7="lab",SETTINGS!$F$24,SETTINGS!$F$31)) -> 0 | Y7: 0 | Z7: =Y7*(0.01*IF(#REF!="ONLINE", SETTINGS!$F$26, IF('MID-FINAL'!#REF!="BLENDED",SETTINGS!$F$34, IF('MID-FINAL'!#REF!="MODULAR",SETTINGS!$F$42)))) -> #REF! | AB7: =AA7/$AA$6*50+50 -> 50 | AC7: =AB7*(0.01*IF(D7="lab",SETTINGS!$F$25,"0")) -> 0 | AE7: =AD7/$AD$6*50+50 -> 50 | AF7: =AE7*(0.01*IF(D7="lab",SETTINGS!$F$26,SETTINGS!$F$32)) -> 0 | AG7: =IF(U7<=40,"DRP",AF7+AC7+X7+V7+T7+L7) -> 0 | AN7: =SUM(AI7:AM7) -> 0 | AO7: =AN7/$AN$6*50+50 -> 50 | AP7: =AO7*(0.01*IF(D7="lab",SETTINGS!$F$22,SETTINGS!$F$29)) -> 0 | AV7: =SUM(AQ7:AU7) -> 0 | AW7: =AV7/$AV$6*50+50 -> 50 | AX7: =AW7*(0.01*IF(D7="lab",SETTINGS!$F$23,SETTINGS!$F$30)) -> 0 | AY7: =ATT!AJ6 -> 90 | AZ7: =AY7*(0.01*IF(D7="lab",SETTINGS!$F$21,SETTINGS!$F$28)) -> 0 | BA7: 100 | BB7: =BA7*(0.01*IF(D7="lab",SETTINGS!$F$24,SETTINGS!$F$31)) -> 0 | BD7: =BC7/$BC$6*50+50 -> 50 | BE7: =BD7*(0.01*IF(D7="lab",SETTINGS!$F$25,"0")) -> 0 | BG7: =BF7/$BF$6*50+50 -> 50 | BH7: =BG7*(0.01*IF(D7="lab",SETTINGS!$F$26,SETTINGS!$F$32)) -> 0 | BI7: =IF(AG7="DRP","DRP",IF(AY7<=40,"FA",BH7+BE7+BB7+AZ7+AX7+AP7)) -> 0
B8: 2 | C8: =SETTINGS!C11 -> 0 | D8: Non-Lab | J8: =SUM(E8:I8) -> 0 | K8: =J8/$J$6*50+50 -> 50 | L8: =K8*(0.01*IF(D8="lab",SETTINGS!$F$22,SETTINGS!$F$29)) -> 0 | R8: =SUM(M8:Q8) -> 0 | S8: =R8/$R$6*50+50 -> 50 | T8: =S8*(0.01*IF(D8="lab",SETTINGS!$F$23,SETTINGS!$F$30)) -> 0 | U8: =ATT!S7 -> 100 | V8: =U8*(0.01*IF(D8="lab",SETTINGS!$F$21,SETTINGS!$F$28)) -> 0 | W8: 100 | X8: =W8*(0.01*IF(D8="lab",SETTINGS!$F$24,SETTINGS!$F$31)) -> 0 | Y8: 0 | Z8: =Y8*(0.01*IF(#REF!="ONLINE", SETTINGS!$F$26, IF('MID-FINAL'!#REF!="BLENDED",SETTINGS!$F$34, IF('MID-FINAL'!#REF!="MODULAR",SETTINGS!$F$42)))) -> #REF! | AB8: =AA8/$AA$6*50+50 -> 50 | AC8: =AB8*(0.01*IF(D8="lab",SETTINGS!$F$25,"0")) -> 0 | AE8: =AD8/$AD$6*50+50 -> 50 | AF8: =AE8*(0.01*IF(D8="lab",SETTINGS!$F$26,SETTINGS!$F$32)) -> 0 | AG8: =IF(U8<=40,"DRP",AF8+AC8+X8+V8+T8+L8) -> 0 | AN8: =SUM(AI8:AM8) -> 0 | AO8: =AN8/$AN$6*50+50 -> 50 | AP8: =AO8*(0.01*IF(D8="lab",SETTINGS!$F$22,SETTINGS!$F$29)) -> 0 | AV8: =SUM(AQ8:AU8) -> 0 | AW8: =AV8/$AV$6*50+50 -> 50 | AX8: =AW8*(0.01*IF(D8="lab",SETTINGS!$F$23,SETTINGS!$F$30)) -> 0 | AY8: =ATT!AJ7 -> 100 | AZ8: =AY8*(0.01*IF(D8="lab",SETTINGS!$F$21,SETTINGS!$F$28)) -> 0 | BA8: 100 | BB8: =BA8*(0.01*IF(D8="lab",SETTINGS!$F$24,SETTINGS!$F$31)) -> 0 | BD8: =BC8/$BC$6*50+50 -> 50 | BE8: =BD8*(0.01*IF(D8="lab",SETTINGS!$F$25,"0")) -> 0 | BG8: =BF8/$BF$6*50+50 -> 50 | BH8: =BG8*(0.01*IF(D8="lab",SETTINGS!$F$26,SETTINGS!$F$32)) -> 0 | BI8: =IF(AG8="DRP","DRP",IF(AY8<=40,"FA",BH8+BE8+BB8+AZ8+AX8+AP8)) -> 0
B9: 3 | C9: =SETTINGS!C12 -> 0 | D9: Non-Lab | J9: =SUM(E9:I9) -> 0 | K9: =J9/$J$6*50+50 -> 50 | L9: =K9*(0.01*IF(D9="lab",SETTINGS!$F$22,SETTINGS!$F$29)) -> 0 | R9: =SUM(M9:Q9) -> 0 | S9: =R9/$R$6*50+50 -> 50 | T9: =S9*(0.01*IF(D9="lab",SETTINGS!$F$23,SETTINGS!$F$30)) -> 0 | U9: =ATT!S8 -> 100 | V9: =U9*(0.01*IF(D9="lab",SETTINGS!$F$21,SETTINGS!$F$28)) -> 0 | W9: 100 | X9: =W9*(0.01*IF(D9="lab",SETTINGS!$F$24,SETTINGS!$F$31)) -> 0 | Y9: 0 | Z9: =Y9*(0.01*IF(#REF!="ONLINE", SETTINGS!$F$26, IF('MID-FINAL'!#REF!="BLENDED",SETTINGS!$F$34, IF('MID-FINAL'!#REF!="MODULAR",SETTINGS!$F$42)))) -> #REF! | AB9: =AA9/$AA$6*50+50 -> 50 | AC9: =AB9*(0.01*IF(D9="lab",SETTINGS!$F$25,"0")) -> 0 | AE9: =AD9/$AD$6*50+50 -> 50 | AF9: =AE9*(0.01*IF(D9="lab",SETTINGS!$F$26,SETTINGS!$F$32)) -> 0 | AG9: =IF(U9<=40,"DRP",AF9+AC9+X9+V9+T9+L9) -> 0 | AN9: =SUM(AI9:AM9) -> 0 | AO9: =AN9/$AN$6*50+50 -> 50 | AP9: =AO9*(0.01*IF(D9="lab",SETTINGS!$F$22,SETTINGS!$F$29)) -> 0 | AV9: =SUM(AQ9:AU9) -> 0 | AW9: =AV9/$AV$6*50+50 -> 50 | AX9: =AW9*(0.01*IF(D9="lab",SETTINGS!$F$23,SETTINGS!$F$30)) -> 0 | AY9: =ATT!AJ8 -> 100 | AZ9: =AY9*(0.01*IF(D9="lab",SETTINGS!$F$21,SETTINGS!$F$28)) -> 0 | BA9: 100 | BB9: =BA9*(0.01*IF(D9="lab",SETTINGS!$F$24,SETTINGS!$F$31)) -> 0 | BD9: =BC9/$BC$6*50+50 -> 50 | BE9: =BD9*(0.01*IF(D9="lab",SETTINGS!$F$25,"0")) -> 0 | BG9: =BF9/$BF$6*50+50 -> 50 | BH9: =BG9*(0.01*IF(D9="lab",SETTINGS!$F$26,SETTINGS!$F$32)) -> 0 | BI9: =IF(AG9="DRP","DRP",IF(AY9<=40,"FA",BH9+BE9+BB9+AZ9+AX9+AP9)) -> 0
B10: 4 | C10: =SETTINGS!C13 -> 0 | D10: Non-Lab | J10: =SUM(E10:I10) -> 0 | K10: =J10/$J$6*50+50 -> 50 | L10: =K10*(0.01*IF(D10="lab",SETTINGS!$F$22,SETTINGS!$F$29)) -> 0 | R10: =SUM(M10:Q10) -> 0 | S10: =R10/$R$6*50+50 -> 50 | T10: =S10*(0.01*IF(D10="lab",SETTINGS!$F$23,SETTINGS!$F$30)) -> 0 | U10: =ATT!S9 -> 100 | V10: =U10*(0.01*IF(D10="lab",SETTINGS!$F$21,SETTINGS!$F$28)) -> 0 | W10: 100 | X10: =W10*(0.01*IF(D10="lab",SETTINGS!$F$24,SETTINGS!$F$31)) -> 0 | Y10: 0 | Z10: =Y10*(0.01*IF(#REF!="ONLINE", SETTINGS!$F$26, IF('MID-FINAL'!#REF!="BLENDED",SETTINGS!$F$34, IF('MID-FINAL'!#REF!="MODULAR",SETTINGS!$F$42)))) -> #REF! | AB10: =AA10/$AA$6*50+50 -> 50 | AC10: =AB10*(0.01*IF(D10="lab",SETTINGS!$F$25,"0")) -> 0 | AE10: =AD10/$AD$6*50+50 -> 50 | AF10: =AE10*(0.01*IF(D10="lab",SETTINGS!$F$26,SETTINGS!$F$32)) -> 0 | AG10: =IF(U10<=40,"DRP",AF10+AC10+X10+V10+T10+L10) -> 0 | AN10: =SUM(AI10:AM10) -> 0 | AO10: =AN10/$AN$6*50+50 -> 50 | AP10: =AO10*(0.01*IF(D10="lab",SETTINGS!$F$22,SETTINGS!$F$29)) -> 0 | AV10: =SUM(AQ10:AU10) -> 0 | AW10: =AV10/$AV$6*50+50 -> 50 | AX10: =AW10*(0.01*IF(D10="lab",SETTINGS!$F$23,SETTINGS!$F$30)) -> 0 | AY10: =ATT!AJ9 -> 100 | AZ10: =AY10*(0.01*IF(D10="lab",SETTINGS!$F$21,SETTINGS!$F$28)) -> 0 | BA10: 100 | BB10: =BA10*(0.01*IF(D10="lab",SETTINGS!$F$24,SETTINGS!$F$31)) -> 0 | BD10: =BC10/$BC$6*50+50 -> 50 | BE10: =BD10*(0.01*IF(D10="lab",SETTINGS!$F$25,"0")) -> 0 | BG10: =BF10/$BF$6*50+50 -> 50 | BH10: =BG10*(0.01*IF(D10="lab",SETTINGS!$F$26,SETTINGS!$F$32)) -> 0 | BI10: =IF(AG10="DRP","DRP",IF(AY10<=40,"FA",BH10+BE10+BB10+AZ10+AX10+AP10)) -> 0
B11: 5 | C11: =SETTINGS!C14 -> 0 | D11: Non-Lab | J11: =SUM(E11:I11) -> 0 | K11: =J11/$J$6*50+50 -> 50 | L11: =K11*(0.01*IF(D11="lab",SETTINGS!$F$22,SETTINGS!$F$29)) -> 0 | R11: =SUM(M11:Q11) -> 0 | S11: =R11/$R$6*50+50 -> 50 | T11: =S11*(0.01*IF(D11="lab",SETTINGS!$F$23,SETTINGS!$F$30)) -> 0 | U11: =ATT!S10 -> 100 | V11: =U11*(0.01*IF(D11="lab",SETTINGS!$F$21,SETTINGS!$F$28)) -> 0 | W11: 100 | X11: =W11*(0.01*IF(D11="lab",SETTINGS!$F$24,SETTINGS!$F$31)) -> 0 | Y11: 0 | Z11: =Y11*(0.01*IF(#REF!="ONLINE", SETTINGS!$F$26, IF('MID-FINAL'!#REF!="BLENDED",SETTINGS!$F$34, IF('MID-FINAL'!#REF!="MODULAR",SETTINGS!$F$42)))) -> #REF! | AB11: =AA11/$AA$6*50+50 -> 50 | AC11: =AB11*(0.01*IF(D11="lab",SETTINGS!$F$25,"0")) -> 0 | AE11: =AD11/$AD$6*50+50 -> 50 | AF11: =AE11*(0.01*IF(D11="lab",SETTINGS!$F$26,SETTINGS!$F$32)) -> 0 | AG11: =IF(U11<=40,"DRP",AF11+AC11+X11+V11+T11+L11) -> 0 | AN11: =SUM(AI11:AM11) -> 0 | AO11: =AN11/$AN$6*50+50 -> 50 | AP11: =AO11*(0.01*IF(D11="lab",SETTINGS!$F$22,SETTINGS!$F$29)) -> 0 | AV11: =SUM(AQ11:AU11) -> 0 | AW11: =AV11/$AV$6*50+50 -> 50 | AX11: =AW11*(0.01*IF(D11="lab",SETTINGS!$F$23,SETTINGS!$F$30)) -> 0 | AY11: =ATT!AJ10 -> 100 | AZ11: =AY11*(0.01*IF(D11="lab",SETTINGS!$F$21,SETTINGS!$F$28)) -> 0 | BA11: 100 | BB11: =BA11*(0.01*IF(D11="lab",SETTINGS!$F$24,SETTINGS!$F$31)) -> 0 | BD11: =BC11/$BC$6*50+50 -> 50 | BE11: =BD11*(0.01*IF(D11="lab",SETTINGS!$F$25,"0")) -> 0 | BG11: =BF11/$BF$6*50+50 -> 50 | BH11: =BG11*(0.01*IF(D11="lab",SETTINGS!$F$26,SETTINGS!$F$32)) -> 0 | BI11: =IF(AG11="DRP","DRP",IF(AY11<=40,"FA",BH11+BE11+BB11+AZ11+AX11+AP11)) -> 0
B12: 6 | C12: =SETTINGS!C15 -> 0 | D12: Non-Lab | J12: =SUM(E12:I12) -> 0 | K12: =J12/$J$6*50+50 -> 50 | L12: =K12*(0.01*IF(D12="lab",SETTINGS!$F$22,SETTINGS!$F$29)) -> 0 | R12: =SUM(M12:Q12) -> 0 | S12: =R12/$R$6*50+50 -> 50 | T12: =S12*(0.01*IF(D12="lab",SETTINGS!$F$23,SETTINGS!$F$30)) -> 0 | U12: =ATT!S11 -> 100 | V12: =U12*(0.01*IF(D12="lab",SETTINGS!$F$21,SETTINGS!$F$28)) -> 0 | W12: 100 | X12: =W12*(0.01*IF(D12="lab",SETTINGS!$F$24,SETTINGS!$F$31)) -> 0 | Y12: 0 | Z12: =Y12*(0.01*IF(#REF!="ONLINE", SETTINGS!$F$26, IF('MID-FINAL'!#REF!="BLENDED",SETTINGS!$F$34, IF('MID-FINAL'!#REF!="MODULAR",SETTINGS!$F$42)))) -> #REF! | AB12: =AA12/$AA$6*50+50 -> 50 | AC12: =AB12*(0.01*IF(D12="lab",SETTINGS!$F$25,"0")) -> 0 | AE12: =AD12/$AD$6*50+50 -> 50 | AF12: =AE12*(0.01*IF(D12="lab",SETTINGS!$F$26,SETTINGS!$F$32)) -> 0 | AG12: =IF(U12<=40,"DRP",AF12+AC12+X12+V12+T12+L12) -> 0 | AN12: =SUM(AI12:AM12) -> 0 | AO12: =AN12/$AN$6*50+50 -> 50 | AP12: =AO12*(0.01*IF(D12="lab",SETTINGS!$F$22,SETTINGS!$F$29)) -> 0 | AV12: =SUM(AQ12:AU12) -> 0 | AW12: =AV12/$AV$6*50+50 -> 50 | AX12: =AW12*(0.01*IF(D12="lab",SETTINGS!$F$23,SETTINGS!$F$30)) -> 0 | AY12: =ATT!AJ11 -> 100 | AZ12: =AY12*(0.01*IF(D12="lab",SETTINGS!$F$21,SETTINGS!$F$28)) -> 0 | BA12: 100 | BB12: =BA12*(0.01*IF(D12="lab",SETTINGS!$F$24,SETTINGS!$F$31)) -> 0 | BD12: =BC12/$BC$6*50+50 -> 50 | BE12: =BD12*(0.01*IF(D12="lab",SETTINGS!$F$25,"0")) -> 0 | BG12: =BF12/$BF$6*50+50 -> 50 | BH12: =BG12*(0.01*IF(D12="lab",SETTINGS!$F$26,SETTINGS!$F$32)) -> 0 | BI12: =IF(AG12="DRP","DRP",IF(AY12<=40,"FA",BH12+BE12+BB12+AZ12+AX12+AP12)) -> 0
B13: 7 | C13: =SETTINGS!C16 -> 0 | D13: Non-Lab | J13: =SUM(E13:I13) -> 0 | K13: =J13/$J$6*50+50 -> 50 | L13: =K13*(0.01*IF(D13="lab",SETTINGS!$F$22,SETTINGS!$F$29)) -> 0 | R13: =SUM(M13:Q13) -> 0 | S13: =R13/$R$6*50+50 -> 50 | T13: =S13*(0.01*IF(D13="lab",SETTINGS!$F$23,SETTINGS!$F$30)) -> 0 | U13: =ATT!S12 -> 100 | V13: =U13*(0.01*IF(D13="lab",SETTINGS!$F$21,SETTINGS!$F$28)) -> 0 | W13: 100 | X13: =W13*(0.01*IF(D13="lab",SETTINGS!$F$24,SETTINGS!$F$31)) -> 0 | Y13: 0 | Z13: =Y13*(0.01*IF(#REF!="ONLINE", SETTINGS!$F$26, IF('MID-FINAL'!#REF!="BLENDED",SETTINGS!$F$34, IF('MID-FINAL'!#REF!="MODULAR",SETTINGS!$F$42)))) -> #REF! | AB13: =AA13/$AA$6*50+50 -> 50 | AC13: =AB13*(0.01*IF(D13="lab",SETTINGS!$F$25,"0")) -> 0 | AE13: =AD13/$AD$6*50+50 -> 50 | AF13: =AE13*(0.01*IF(D13="lab",SETTINGS!$F$26,SETTINGS!$F$32)) -> 0 | AG13: =IF(U13<=40,"DRP",AF13+AC13+X13+V13+T13+L13) -> 0 | AN13: =SUM(AI13:AM13) -> 0 | AO13: =AN13/$AN$6*50+50 -> 50 | AP13: =AO13*(0.01*IF(D13="lab",SETTINGS!$F$22,SETTINGS!$F$29)) -> 0 | AV13: =SUM(AQ13:AU13) -> 0 | AW13: =AV13/$AV$6*50+50 -> 50 | AX13: =AW13*(0.01*IF(D13="lab",SETTINGS!$F$23,SETTINGS!$F$30)) -> 0 | AY13: =ATT!AJ12 -> 100 | AZ13: =AY13*(0.01*IF(D13="lab",SETTINGS!$F$21,SETTINGS!$F$28)) -> 0 | BA13: 100 | BB13: =BA13*(0.01*IF(D13="lab",SETTINGS!$F$24,SETTINGS!$F$31)) -> 0 | BD13: =BC13/$BC$6*50+50 -> 50 | BE13: =BD13*(0.01*IF(D13="lab",SETTINGS!$F$25,"0")) -> 0 | BG13: =BF13/$BF$6*50+50 -> 50 | BH13: =BG13*(0.01*IF(D13="lab",SETTINGS!$F$26,SETTINGS!$F$32)) -> 0 | BI13: =IF(AG13="DRP","DRP",IF(AY13<=40,"FA",BH13+BE13+BB13+AZ13+AX13+AP13)) -> 0
B14: 8 | C14: =SETTINGS!C17 -> 0 | D14: Non-Lab | J14: =SUM(E14:I14) -> 0 | K14: =J14/$J$6*50+50 -> 50 | L14: =K14*(0.01*IF(D14="lab",SETTINGS!$F$22,SETTINGS!$F$29)) -> 0 | R14: =SUM(M14:Q14) -> 0 | S14: =R14/$R$6*50+50 -> 50 | T14: =S14*(0.01*IF(D14="lab",SETTINGS!$F$23,SETTINGS!$F$30)) -> 0 | U14: =ATT!S13 -> 100 | V14: =U14*(0.01*IF(D14="lab",SETTINGS!$F$21,SETTINGS!$F$28)) -> 0 | W14: 100 | X14: =W14*(0.01*IF(D14="lab",SETTINGS!$F$24,SETTINGS!$F$31)) -> 0 | Y14: 0 | Z14: =Y14*(0.01*IF(#REF!="ONLINE", SETTINGS!$F$26, IF('MID-FINAL'!#REF!="BLENDED",SETTINGS!$F$34, IF('MID-FINAL'!#REF!="MODULAR",SETTINGS!$F$42)))) -> #REF! | AB14: =AA14/$AA$6*50+50 -> 50 | AC14: =AB14*(0.01*IF(D14="lab",SETTINGS!$F$25,"0")) -> 0 | AE14: =AD14/$AD$6*50+50 -> 50 | AF14: =AE14*(0.01*IF(D14="lab",SETTINGS!$F$26,SETTINGS!$F$32)) -> 0 | AG14: =IF(U14<=40,"DRP",AF14+AC14+X14+V14+T14+L14) -> 0 | AN14: =SUM(AI14:AM14) -> 0 | AO14: =AN14/$AN$6*50+50 -> 50 | AP14: =AO14*(0.01*IF(D14="lab",SETTINGS!$F$22,SETTINGS!$F$29)) -> 0 | AV14: =SUM(AQ14:AU14) -> 0 | AW14: =AV14/$AV$6*50+50 -> 50 | AX14: =AW14*(0.01*IF(D14="lab",SETTINGS!$F$23,SETTINGS!$F$30)) -> 0 | AY14: =ATT!AJ13 -> 100 | AZ14: =AY14*(0.01*IF(D14="lab",SETTINGS!$F$21,SETTINGS!$F$28)) -> 0 | BA14: 100 | BB14: =BA14*(0.01*IF(D14="lab",SETTINGS!$F$24,SETTINGS!$F$31)) -> 0 | BD14: =BC14/$BC$6*50+50 -> 50 | BE14: =BD14*(0.01*IF(D14="lab",SETTINGS!$F$25,"0")) -> 0 | BG14: =BF14/$BF$6*50+50 -> 50 | BH14: =BG14*(0.01*IF(D14="lab",SETTINGS!$F$26,SETTINGS!$F$32)) -> 0 | BI14: =IF(AG14="DRP","DRP",IF(AY14<=40,"FA",BH14+BE14+BB14+AZ14+AX14+AP14)) -> 0
B15: 9 | C15: =SETTINGS!C18 -> 0 | D15: Non-Lab | J15: =SUM(E15:I15) -> 0 | K15: =J15/$J$6*50+50 -> 50 | L15: =K15*(0.01*IF(D15="lab",SETTINGS!$F$22,SETTINGS!$F$29)) -> 0 | R15: =SUM(M15:Q15) -> 0 | S15: =R15/$R$6*50+50 -> 50 | T15: =S15*(0.01*IF(D15="lab",SETTINGS!$F$23,SETTINGS!$F$30)) -> 0 | U15: =ATT!S14 -> 100 | V15: =U15*(0.01*IF(D15="lab",SETTINGS!$F$21,SETTINGS!$F$28)) -> 0 | W15: 100 | X15: =W15*(0.01*IF(D15="lab",SETTINGS!$F$24,SETTINGS!$F$31)) -> 0 | Y15: 0 | Z15: =Y15*(0.01*IF(#REF!="ONLINE", SETTINGS!$F$26, IF('MID-FINAL'!#REF!="BLENDED",SETTINGS!$F$34, IF('MID-FINAL'!#REF!="MODULAR",SETTINGS!$F$42)))) -> #REF! | AB15: =AA15/$AA$6*50+50 -> 50 | AC15: =AB15*(0.01*IF(D15="lab",SETTINGS!$F$25,"0")) -> 0 | AE15: =AD15/$AD$6*50+50 -> 50 | AF15: =AE15*(0.01*IF(D15="lab",SETTINGS!$F$26,SETTINGS!$F$32)) -> 0 | AG15: =IF(U15<=40,"DRP",AF15+AC15+X15+V15+T15+L15) -> 0 | AN15: =SUM(AI15:AM15) -> 0 | AO15: =AN15/$AN$6*50+50 -> 50 | AP15: =AO15*(0.01*IF(D15="lab",SETTINGS!$F$22,SETTINGS!$F$29)) -> 0 | AV15: =SUM(AQ15:AU15) -> 0 | AW15: =AV15/$AV$6*50+50 -> 50 | AX15: =AW15*(0.01*IF(D15="lab",SETTINGS!$F$23,SETTINGS!$F$30)) -> 0 | AY15: =ATT!AJ14 -> 100 | AZ15: =AY15*(0.01*IF(D15="lab",SETTINGS!$F$21,SETTINGS!$F$28)) -> 0 | BA15: 100 | BB15: =BA15*(0.01*IF(D15="lab",SETTINGS!$F$24,SETTINGS!$F$31)) -> 0 | BD15: =BC15/$BC$6*50+50 -> 50 | BE15: =BD15*(0.01*IF(D15="lab",SETTINGS!$F$25,"0")) -> 0 | BG15: =BF15/$BF$6*50+50 -> 50 | BH15: =BG15*(0.01*IF(D15="lab",SETTINGS!$F$26,SETTINGS!$F$32)) -> 0 | BI15: =IF(AG15="DRP","DRP",IF(AY15<=40,"FA",BH15+BE15+BB15+AZ15+AX15+AP15)) -> 0
B16: 10 | C16: =SETTINGS!C19 -> 0 | D16: Non-Lab | J16: =SUM(E16:I16) -> 0 | K16: =J16/$J$6*50+50 -> 50 | L16: =K16*(0.01*IF(D16="lab",SETTINGS!$F$22,SETTINGS!$F$29)) -> 0 | R16: =SUM(M16:Q16) -> 0 | S16: =R16/$R$6*50+50 -> 50 | T16: =S16*(0.01*IF(D16="lab",SETTINGS!$F$23,SETTINGS!$F$30)) -> 0 | U16: =ATT!S15 -> 100 | V16: =U16*(0.01*IF(D16="lab",SETTINGS!$F$21,SETTINGS!$F$28)) -> 0 | W16: 100 | X16: =W16*(0.01*IF(D16="lab",SETTINGS!$F$24,SETTINGS!$F$31)) -> 0 | Y16: 0 | Z16: =Y16*(0.01*IF(#REF!="ONLINE", SETTINGS!$F$26, IF('MID-FINAL'!#REF!="BLENDED",SETTINGS!$F$34, IF('MID-FINAL'!#REF!="MODULAR",SETTINGS!$F$42)))) -> #REF! | AB16: =AA16/$AA$6*50+50 -> 50 | AC16: =AB16*(0.01*IF(D16="lab",SETTINGS!$F$25,"0")) -> 0 | AE16: =AD16/$AD$6*50+50 -> 50 | AF16: =AE16*(0.01*IF(D16="lab",SETTINGS!$F$26,SETTINGS!$F$32)) -> 0 | AG16: =IF(U16<=40,"DRP",AF16+AC16+X16+V16+T16+L16) -> 0 | AN16: =SUM(AI16:AM16) -> 0 | AO16: =AN16/$AN$6*50+50 -> 50 | AP16: =AO16*(0.01*IF(D16="lab",SETTINGS!$F$22,SETTINGS!$F$29)) -> 0 | AV16: =SUM(AQ16:AU16) -> 0 | AW16: =AV16/$AV$6*50+50 -> 50 | AX16: =AW16*(0.01*IF(D16="lab",SETTINGS!$F$23,SETTINGS!$F$30)) -> 0 | AY16: =ATT!AJ15 -> 100 | AZ16: =AY16*(0.01*IF(D16="lab",SETTINGS!$F$21,SETTINGS!$F$28)) -> 0 | BA16: 100 | BB16: =BA16*(0.01*IF(D16="lab",SETTINGS!$F$24,SETTINGS!$F$31)) -> 0 | BD16: =BC16/$BC$6*50+50 -> 50 | BE16: =BD16*(0.01*IF(D16="lab",SETTINGS!$F$25,"0")) -> 0 | BG16: =BF16/$BF$6*50+50 -> 50 | BH16: =BG16*(0.01*IF(D16="lab",SETTINGS!$F$26,SETTINGS!$F$32)) -> 0 | BI16: =IF(AG16="DRP","DRP",IF(AY16<=40,"FA",BH16+BE16+BB16+AZ16+AX16+AP16)) -> 0
B17: 11 | C17: =SETTINGS!C20 -> 0 | D17: Non-Lab | J17: =SUM(E17:I17) -> 0 | K17: =J17/$J$6*50+50 -> 50 | L17: =K17*(0.01*IF(D17="lab",SETTINGS!$F$22,SETTINGS!$F$29)) -> 0 | R17: =SUM(M17:Q17) -> 0 | S17: =R17/$R$6*50+50 -> 50 | T17: =S17*(0.01*IF(D17="lab",SETTINGS!$F$23,SETTINGS!$F$30)) -> 0 | U17: =ATT!S16 -> 100 | V17: =U17*(0.01*IF(D17="lab",SETTINGS!$F$21,SETTINGS!$F$28)) -> 0 | W17: 100 | X17: =W17*(0.01*IF(D17="lab",SETTINGS!$F$24,SETTINGS!$F$31)) -> 0 | Y17: 0 | Z17: =Y17*(0.01*IF(#REF!="ONLINE", SETTINGS!$F$26, IF('MID-FINAL'!#REF!="BLENDED",SETTINGS!$F$34, IF('MID-FINAL'!#REF!="MODULAR",SETTINGS!$F$42)))) -> #REF! | AB17: =AA17/$AA$6*50+50 -> 50 | AC17: =AB17*(0.01*IF(D17="lab",SETTINGS!$F$25,"0")) -> 0 | AE17: =AD17/$AD$6*50+50 -> 50 | AF17: =AE17*(0.01*IF(D17="lab",SETTINGS!$F$26,SETTINGS!$F$32)) -> 0 | AG17: =IF(U17<=40,"DRP",AF17+AC17+X17+V17+T17+L17) -> 0 | AN17: =SUM(AI17:AM17) -> 0 | AO17: =AN17/$AN$6*50+50 -> 50 | AP17: =AO17*(0.01*IF(D17="lab",SETTINGS!$F$22,SETTINGS!$F$29)) -> 0 | AV17: =SUM(AQ17:AU17) -> 0 | AW17: =AV17/$AV$6*50+50 -> 50 | AX17: =AW17*(0.01*IF(D17="lab",SETTINGS!$F$23,SETTINGS!$F$30)) -> 0 | AY17: =ATT!AJ16 -> 100 | AZ17: =AY17*(0.01*IF(D17="lab",SETTINGS!$F$21,SETTINGS!$F$28)) -> 0 | BA17: 100 | BB17: =BA17*(0.01*IF(D17="lab",SETTINGS!$F$24,SETTINGS!$F$31)) -> 0 | BD17: =BC17/$BC$6*50+50 -> 50 | BE17: =BD17*(0.01*IF(D17="lab",SETTINGS!$F$25,"0")) -> 0 | BG17: =BF17/$BF$6*50+50 -> 50 | BH17: =BG17*(0.01*IF(D17="lab",SETTINGS!$F$26,SETTINGS!$F$32)) -> 0 | BI17: =IF(AG17="DRP","DRP",IF(AY17<=40,"FA",BH17+BE17+BB17+AZ17+AX17+AP17)) -> 0
B18: 12 | C18: =SETTINGS!C21 -> 0 | D18: Non-Lab | J18: =SUM(E18:I18) -> 0 | K18: =J18/$J$6*50+50 -> 50 | L18: =K18*(0.01*IF(D18="lab",SETTINGS!$F$22,SETTINGS!$F$29)) -> 0 | R18: =SUM(M18:Q18) -> 0 | S18: =R18/$R$6*50+50 -> 50 | T18: =S18*(0.01*IF(D18="lab",SETTINGS!$F$23,SETTINGS!$F$30)) -> 0 | U18: =ATT!S17 -> 100 | V18: =U18*(0.01*IF(D18="lab",SETTINGS!$F$21,SETTINGS!$F$28)) -> 0 | W18: 100 | X18: =W18*(0.01*IF(D18="lab",SETTINGS!$F$24,SETTINGS!$F$31)) -> 0 | Y18: 0 | Z18: =Y18*(0.01*IF(#REF!="ONLINE", SETTINGS!$F$26, IF('MID-FINAL'!#REF!="BLENDED",SETTINGS!$F$34, IF('MID-FINAL'!#REF!="MODULAR",SETTINGS!$F$42)))) -> #REF! | AB18: =AA18/$AA$6*50+50 -> 50 | AC18: =AB18*(0.01*IF(D18="lab",SETTINGS!$F$25,"0")) -> 0 | AE18: =AD18/$AD$6*50+50 -> 50 | AF18: =AE18*(0.01*IF(D18="lab",SETTINGS!$F$26,SETTINGS!$F$32)) -> 0 | AG18: =IF(U18<=40,"DRP",AF18+AC18+X18+V18+T18+L18) -> 0 | AN18: =SUM(AI18:AM18) -> 0 | AO18: =AN18/$AN$6*50+50 -> 50 | AP18: =AO18*(0.01*IF(D18="lab",SETTINGS!$F$22,SETTINGS!$F$29)) -> 0 | AV18: =SUM(AQ18:AU18) -> 0 | AW18: =AV18/$AV$6*50+50 -> 50 | AX18: =AW18*(0.01*IF(D18="lab",SETTINGS!$F$23,SETTINGS!$F$30)) -> 0 | AY18: =ATT!AJ17 -> 100 | AZ18: =AY18*(0.01*IF(D18="lab",SETTINGS!$F$21,SETTINGS!$F$28)) -> 0 | BA18: 100 | BB18: =BA18*(0.01*IF(D18="lab",SETTINGS!$F$24,SETTINGS!$F$31)) -> 0 | BD18: =BC18/$BC$6*50+50 -> 50 | BE18: =BD18*(0.01*IF(D18="lab",SETTINGS!$F$25,"0")) -> 0 | BG18: =BF18/$BF$6*50+50 -> 50 | BH18: =BG18*(0.01*IF(D18="lab",SETTINGS!$F$26,SETTINGS!$F$32)) -> 0 | BI18: =IF(AG18="DRP","DRP",IF(AY18<=40,"FA",BH18+BE18+BB18+AZ18+AX18+AP18)) -> 0
... B66: 60 | C66: =SETTINGS!C69 -> 0 | D66: Non-Lab | J66: =SUM(E66:I66) -> 0 | K66: =J66/$J$6*50+50 -> 50 | L66: =K66*(0.01*IF(D66="lab",SETTINGS!$F$22,SETTINGS!$F$29)) -> 0 | R66: =SUM(M66:Q66) -> 0 | S66: =R66/$R$6*50+50 -> 50 | T66: =S66*(0.01*IF(D66="lab",SETTINGS!$F$23,SETTINGS!$F$30)) -> 0 | U66: =ATT!S65 -> 100 | V66: =U66*(0.01*IF(D66="lab",SETTINGS!$F$21,SETTINGS!$F$28)) -> 0 | W66: 100 | X66: =W66*(0.01*IF(D66="lab",SETTINGS!$F$24,SETTINGS!$F$31)) -> 0 | Y66: 0 | Z66: =Y66*(0.01*IF(#REF!="ONLINE", SETTINGS!$F$26, IF('MID-FINAL'!#REF!="BLENDED",SETTINGS!$F$34, IF('MID-FINAL'!#REF!="MODULAR",SETTINGS!$F$42)))) -> #REF! | AB66: =AA66/$AA$6*50+50 -> 50 | AC66: =AB66*(0.01*IF(D66="lab",SETTINGS!$F$25,"0")) -> 0 | AE66: =AD66/$AD$6*50+50 -> 50 | AF66: =AE66*(0.01*IF(D66="lab",SETTINGS!$F$26,SETTINGS!$F$32)) -> 0 | AG66: =IF(U66<=40,"DRP",AF66+AC66+X66+V66+T66+L66) -> 0 | AN66: =SUM(AI66:AM66) -> 0 | AO66: =AN66/$AN$6*50+50 -> 50 | AP66: =AO66*(0.01*IF(D66="lab",SETTINGS!$F$22,SETTINGS!$F$29)) -> 0 | AV66: =SUM(AQ66:AU66) -> 0 | AW66: =AV66/$AV$6*50+50 -> 50 | AX66: =AW66*(0.01*IF(D66="lab",SETTINGS!$F$23,SETTINGS!$F$30)) -> 0 | AY66: =ATT!AJ65 -> 100 | AZ66: =AY66*(0.01*IF(D66="lab",SETTINGS!$F$21,SETTINGS!$F$28)) -> 0 | BA66: 100 | BB66: =BA66*(0.01*IF(D66="lab",SETTINGS!$F$24,SETTINGS!$F$31)) -> 0 | BD66: =BC66/$BC$6*50+50 -> 50 | BE66: =BD66*(0.01*IF(D66="lab",SETTINGS!$F$25,"0")) -> 0 | BG66: =BF66/$BF$6*50+50 -> 50 | BH66: =BG66*(0.01*IF(D66="lab",SETTINGS!$F$26,SETTINGS!$F$32)) -> 0 | BI66: =IF(AG66="DRP","DRP",IF(AY66<=40,"FA",BH66+BE66+BB66+AZ66+AX66+AP66)) -> 0
B67: 61 | C67: =SETTINGS!C70 -> 0 | D67: Non-Lab | J67: =SUM(E67:I67) -> 0 | K67: =J67/$J$6*50+50 -> 50 | L67: =K67*(0.01*IF(D67="lab",SETTINGS!$F$22,SETTINGS!$F$29)) -> 0 | R67: =SUM(M67:Q67) -> 0 | S67: =R67/$R$6*50+50 -> 50 | T67: =S67*(0.01*IF(D67="lab",SETTINGS!$F$23,SETTINGS!$F$30)) -> 0 | U67: 100 | V67: =U67*(0.01*IF(D67="lab",SETTINGS!$F$21,SETTINGS!$F$28)) -> 0 | W67: 100 | X67: =W67*(0.01*IF(D67="lab",SETTINGS!$F$24,SETTINGS!$F$31)) -> 0 | Y67: 0 | Z67: =Y67*(0.01*IF(#REF!="ONLINE", SETTINGS!$F$26, IF('MID-FINAL'!#REF!="BLENDED",SETTINGS!$F$34, IF('MID-FINAL'!#REF!="MODULAR",SETTINGS!$F$42)))) -> #REF! | AB67: =AA67/$AA$6*50+50 -> 50 | AC67: =AB67*(0.01*IF(D67="lab",SETTINGS!$F$25,"0")) -> 0 | AE67: =AD67/$AD$6*50+50 -> 50 | AF67: =AE67*(0.01*IF(D67="lab",SETTINGS!$F$26,SETTINGS!$F$32)) -> 0 | AG67: =IF(U67<=40,"DRP",AF67+AC67+X67+V67+T67+L67) -> 0 | AN67: =SUM(AI67:AM67) -> 0 | AO67: =AN67/$AN$6*50+50 -> 50 | AP67: =AO67*(0.01*IF(D67="lab",SETTINGS!$F$22,SETTINGS!$F$29)) -> 0 | AV67: =SUM(AQ67:AU67) -> 0 | AW67: =AV67/$AV$6*50+50 -> 50 | AX67: =AW67*(0.01*IF(D67="lab",SETTINGS!$F$23,SETTINGS!$F$30)) -> 0 | AY67: =ATT!AJ66 -> 100 | AZ67: =AY67*(0.01*IF(D67="lab",SETTINGS!$F$21,SETTINGS!$F$28)) -> 0 | BA67: 100 | BB67: =BA67*(0.01*IF(D67="lab",SETTINGS!$F$24,SETTINGS!$F$31)) -> 0 | BD67: =BC67/$BC$6*50+50 -> 50 | BE67: =BD67*(0.01*IF(D67="lab",SETTINGS!$F$25,"0")) -> 0 | BG67: =BF67/$BF$6*50+50 -> 50 | BH67: =BG67*(0.01*IF(D67="lab",SETTINGS!$F$26,SETTINGS!$F$32)) -> 0 | BI67: =IF(AG67="DRP","DRP",IF(AY67<=40,"FA",BH67+BE67+BB67+AZ67+AX67+AP67)) -> 0
B68: 62 | C68: =SETTINGS!C71 -> 0 | D68: Non-Lab | J68: =SUM(E68:I68) -> 0 | K68: =J68/$J$6*50+50 -> 50 | L68: =K68*(0.01*IF(D68="lab",SETTINGS!$F$22,SETTINGS!$F$29)) -> 0 | R68: =SUM(M68:Q68) -> 0 | S68: =R68/$R$6*50+50 -> 50 | T68: =S68*(0.01*IF(D68="lab",SETTINGS!$F$23,SETTINGS!$F$30)) -> 0 | U68: 100 | V68: =U68*(0.01*IF(D68="lab",SETTINGS!$F$21,SETTINGS!$F$28)) -> 0 | W68: 100 | X68: =W68*(0.01*IF(D68="lab",SETTINGS!$F$24,SETTINGS!$F$31)) -> 0 | Y68: 0 | Z68: =Y68*(0.01*IF(#REF!="ONLINE", SETTINGS!$F$26, IF('MID-FINAL'!#REF!="BLENDED",SETTINGS!$F$34, IF('MID-FINAL'!#REF!="MODULAR",SETTINGS!$F$42)))) -> #REF! | AB68: =AA68/$AA$6*50+50 -> 50 | AC68: =AB68*(0.01*IF(D68="lab",SETTINGS!$F$25,"0")) -> 0 | AE68: =AD68/$AD$6*50+50 -> 50 | AF68: =AE68*(0.01*IF(D68="lab",SETTINGS!$F$26,SETTINGS!$F$32)) -> 0 | AG68: =IF(U68<=40,"DRP",AF68+AC68+X68+V68+T68+L68) -> 0 | AN68: =SUM(AI68:AM68) -> 0 | AO68: =AN68/$AN$6*50+50 -> 50 | AP68: =AO68*(0.01*IF(D68="lab",SETTINGS!$F$22,SETTINGS!$F$29)) -> 0 | AV68: =SUM(AQ68:AU68) -> 0 | AW68: =AV68/$AV$6*50+50 -> 50 | AX68: =AW68*(0.01*IF(D68="lab",SETTINGS!$F$23,SETTINGS!$F$30)) -> 0 | AY68: =ATT!AJ67 -> 100 | AZ68: =AY68*(0.01*IF(D68="lab",SETTINGS!$F$21,SETTINGS!$F$28)) -> 0 | BA68: 100 | BB68: =BA68*(0.01*IF(D68="lab",SETTINGS!$F$24,SETTINGS!$F$31)) -> 0 | BD68: =BC68/$BC$6*50+50 -> 50 | BE68: =BD68*(0.01*IF(D68="lab",SETTINGS!$F$25,"0")) -> 0 | BG68: =BF68/$BF$6*50+50 -> 50 | BH68: =BG68*(0.01*IF(D68="lab",SETTINGS!$F$26,SETTINGS!$F$32)) -> 0 | BI68: =IF(AG68="DRP","DRP",IF(AY68<=40,"FA",BH68+BE68+BB68+AZ68+AX68+AP68)) -> 0
B69: 63 | C69: =SETTINGS!C72 -> 0 | D69: Non-Lab | J69: =SUM(E69:I69) -> 0 | K69: =J69/$J$6*50+50 -> 50 | L69: =K69*(0.01*IF(D69="lab",SETTINGS!$F$22,SETTINGS!$F$29)) -> 0 | R69: =SUM(M69:Q69) -> 0 | S69: =R69/$R$6*50+50 -> 50 | T69: =S69*(0.01*IF(D69="lab",SETTINGS!$F$23,SETTINGS!$F$30)) -> 0 | U69: 100 | V69: =U69*(0.01*IF(D69="lab",SETTINGS!$F$21,SETTINGS!$F$28)) -> 0 | W69: 100 | X69: =W69*(0.01*IF(D69="lab",SETTINGS!$F$24,SETTINGS!$F$31)) -> 0 | Y69: 0 | Z69: =Y69*(0.01*IF(#REF!="ONLINE", SETTINGS!$F$26, IF('MID-FINAL'!#REF!="BLENDED",SETTINGS!$F$34, IF('MID-FINAL'!#REF!="MODULAR",SETTINGS!$F$42)))) -> #REF! | AB69: =AA69/$AA$6*50+50 -> 50 | AC69: =AB69*(0.01*IF(D69="lab",SETTINGS!$F$25,"0")) -> 0 | AE69: =AD69/$AD$6*50+50 -> 50 | AF69: =AE69*(0.01*IF(D69="lab",SETTINGS!$F$26,SETTINGS!$F$32)) -> 0 | AG69: =IF(U69<=40,"DRP",AF69+AC69+X69+V69+T69+L69) -> 0 | AN69: =SUM(AI69:AM69) -> 0 | AO69: =AN69/$AN$6*50+50 -> 50 | AP69: =AO69*(0.01*IF(D69="lab",SETTINGS!$F$22,SETTINGS!$F$29)) -> 0 | AV69: =SUM(AQ69:AU69) -> 0 | AW69: =AV69/$AV$6*50+50 -> 50 | AX69: =AW69*(0.01*IF(D69="lab",SETTINGS!$F$23,SETTINGS!$F$30)) -> 0 | AY69: =ATT!AJ68 -> 100 | AZ69: =AY69*(0.01*IF(D69="lab",SETTINGS!$F$21,SETTINGS!$F$28)) -> 0 | BA69: 100 | BB69: =BA69*(0.01*IF(D69="lab",SETTINGS!$F$24,SETTINGS!$F$31)) -> 0 | BD69: =BC69/$BC$6*50+50 -> 50 | BE69: =BD69*(0.01*IF(D69="lab",SETTINGS!$F$25,"0")) -> 0 | BG69: =BF69/$BF$6*50+50 -> 50 | BH69: =BG69*(0.01*IF(D69="lab",SETTINGS!$F$26,SETTINGS!$F$32)) -> 0 | BI69: =IF(AG69="DRP","DRP",IF(AY69<=40,"FA",BH69+BE69+BB69+AZ69+AX69+AP69)) -> 0
B70: 64 | C70: =SETTINGS!C73 -> 0 | D70: Non-Lab | J70: =SUM(E70:I70) -> 0 | K70: =J70/$J$6*50+50 -> 50 | L70: =K70*(0.01*IF(D70="lab",SETTINGS!$F$22,SETTINGS!$F$29)) -> 0 | R70: =SUM(M70:Q70) -> 0 | S70: =R70/$R$6*50+50 -> 50 | T70: =S70*(0.01*IF(D70="lab",SETTINGS!$F$23,SETTINGS!$F$30)) -> 0 | U70: 100 | V70: =U70*(0.01*IF(D70="lab",SETTINGS!$F$21,SETTINGS!$F$28)) -> 0 | W70: 100 | X70: =W70*(0.01*IF(D70="lab",SETTINGS!$F$24,SETTINGS!$F$31)) -> 0 | Y70: 0 | Z70: =Y70*(0.01*IF(#REF!="ONLINE", SETTINGS!$F$26, IF('MID-FINAL'!#REF!="BLENDED",SETTINGS!$F$34, IF('MID-FINAL'!#REF!="MODULAR",SETTINGS!$F$42)))) -> #REF! | AB70: =AA70/$AA$6*50+50 -> 50 | AC70: =AB70*(0.01*IF(D70="lab",SETTINGS!$F$25,"0")) -> 0 | AE70: =AD70/$AD$6*50+50 -> 50 | AF70: =AE70*(0.01*IF(D70="lab",SETTINGS!$F$26,SETTINGS!$F$32)) -> 0 | AG70: =IF(U70<=40,"DRP",AF70+AC70+X70+V70+T70+L70) -> 0 | AN70: =SUM(AI70:AM70) -> 0 | AO70: =AN70/$AN$6*50+50 -> 50 | AP70: =AO70*(0.01*IF(D70="lab",SETTINGS!$F$22,SETTINGS!$F$29)) -> 0 | AV70: =SUM(AQ70:AU70) -> 0 | AW70: =AV70/$AV$6*50+50 -> 50 | AX70: =AW70*(0.01*IF(D70="lab",SETTINGS!$F$23,SETTINGS!$F$30)) -> 0 | AY70: =ATT!AJ69 -> 100 | AZ70: =AY70*(0.01*IF(D70="lab",SETTINGS!$F$21,SETTINGS!$F$28)) -> 0 | BA70: 100 | BB70: =BA70*(0.01*IF(D70="lab",SETTINGS!$F$24,SETTINGS!$F$31)) -> 0 | BD70: =BC70/$BC$6*50+50 -> 50 | BE70: =BD70*(0.01*IF(D70="lab",SETTINGS!$F$25,"0")) -> 0 | BG70: =BF70/$BF$6*50+50 -> 50 | BH70: =BG70*(0.01*IF(D70="lab",SETTINGS!$F$26,SETTINGS!$F$32)) -> 0 | BI70: =IF(AG70="DRP","DRP",IF(AY70<=40,"FA",BH70+BE70+BB70+AZ70+AX70+AP70)) -> 0
B71: 65 | C71: =SETTINGS!C74 -> 0 | D71: Non-Lab | J71: =SUM(E71:I71) -> 0 | K71: =J71/$J$6*50+50 -> 50 | L71: =K71*(0.01*IF(D71="lab",SETTINGS!$F$22,SETTINGS!$F$29)) -> 0 | R71: =SUM(M71:Q71) -> 0 | S71: =R71/$R$6*50+50 -> 50 | T71: =S71*(0.01*IF(D71="lab",SETTINGS!$F$23,SETTINGS!$F$30)) -> 0 | U71: 100 | V71: =U71*(0.01*IF(D71="lab",SETTINGS!$F$21,SETTINGS!$F$28)) -> 0 | W71: 100 | X71: =W71*(0.01*IF(D71="lab",SETTINGS!$F$24,SETTINGS!$F$31)) -> 0 | Y71: 0 | Z71: =Y71*(0.01*IF(#REF!="ONLINE", SETTINGS!$F$26, IF('MID-FINAL'!#REF!="BLENDED",SETTINGS!$F$34, IF('MID-FINAL'!#REF!="MODULAR",SETTINGS!$F$42)))) -> #REF! | AB71: =AA71/$AA$6*50+50 -> 50 | AC71: =AB71*(0.01*IF(D71="lab",SETTINGS!$F$25,"0")) -> 0 | AE71: =AD71/$AD$6*50+50 -> 50 | AF71: =AE71*(0.01*IF(D71="lab",SETTINGS!$F$26,SETTINGS!$F$32)) -> 0 | AG71: =IF(U71<=40,"DRP",AF71+AC71+X71+V71+T71+L71) -> 0 | AN71: =SUM(AI71:AM71) -> 0 | AO71: =AN71/$AN$6*50+50 -> 50 | AP71: =AO71*(0.01*IF(D71="lab",SETTINGS!$F$22,SETTINGS!$F$29)) -> 0 | AV71: =SUM(AQ71:AU71) -> 0 | AW71: =AV71/$AV$6*50+50 -> 50 | AX71: =AW71*(0.01*IF(D71="lab",SETTINGS!$F$23,SETTINGS!$F$30)) -> 0 | AY71: =ATT!AJ70 -> 100 | AZ71: =AY71*(0.01*IF(D71="lab",SETTINGS!$F$21,SETTINGS!$F$28)) -> 0 | BA71: 100 | BB71: =BA71*(0.01*IF(D71="lab",SETTINGS!$F$24,SETTINGS!$F$31)) -> 0 | BD71: =BC71/$BC$6*50+50 -> 50 | BE71: =BD71*(0.01*IF(D71="lab",SETTINGS!$F$25,"0")) -> 0 | BG71: =BF71/$BF$6*50+50 -> 50 | BH71: =BG71*(0.01*IF(D71="lab",SETTINGS!$F$26,SETTINGS!$F$32)) -> 0 | BI71: =IF(AG71="DRP","DRP",IF(AY71<=40,"FA",BH71+BE71+BB71+AZ71+AX71+AP71)) -> 0
B72: 66 | C72: =SETTINGS!C75 -> 0 | D72: Non-Lab | J72: =SUM(E72:I72) -> 0 | K72: =J72/$J$6*50+50 -> 50 | L72: =K72*(0.01*IF(D72="lab",SETTINGS!$F$22,SETTINGS!$F$29)) -> 0 | R72: =SUM(M72:Q72) -> 0 | S72: =R72/$R$6*50+50 -> 50 | T72: =S72*(0.01*IF(D72="lab",SETTINGS!$F$23,SETTINGS!$F$30)) -> 0 | U72: 100 | V72: =U72*(0.01*IF(D72="lab",SETTINGS!$F$21,SETTINGS!$F$28)) -> 0 | W72: 100 | X72: =W72*(0.01*IF(D72="lab",SETTINGS!$F$24,SETTINGS!$F$31)) -> 0 | Y72: 0 | Z72: =Y72*(0.01*IF(#REF!="ONLINE", SETTINGS!$F$26, IF('MID-FINAL'!#REF!="BLENDED",SETTINGS!$F$34, IF('MID-FINAL'!#REF!="MODULAR",SETTINGS!$F$42)))) -> #REF! | AB72: =AA72/$AA$6*50+50 -> 50 | AC72: =AB72*(0.01*IF(D72="lab",SETTINGS!$F$25,"0")) -> 0 | AE72: =AD72/$AD$6*50+50 -> 50 | AF72: =AE72*(0.01*IF(D72="lab",SETTINGS!$F$26,SETTINGS!$F$32)) -> 0 | AG72: =IF(U72<=40,"DRP",AF72+AC72+X72+V72+T72+L72) -> 0 | AN72: =SUM(AI72:AM72) -> 0 | AO72: =AN72/$AN$6*50+50 -> 50 | AP72: =AO72*(0.01*IF(D72="lab",SETTINGS!$F$22,SETTINGS!$F$29)) -> 0 | AV72: =SUM(AQ72:AU72) -> 0 | AW72: =AV72/$AV$6*50+50 -> 50 | AX72: =AW72*(0.01*IF(D72="lab",SETTINGS!$F$23,SETTINGS!$F$30)) -> 0 | AY72: =ATT!AJ71 -> 100 | AZ72: =AY72*(0.01*IF(D72="lab",SETTINGS!$F$21,SETTINGS!$F$28)) -> 0 | BA72: 100 | BB72: =BA72*(0.01*IF(D72="lab",SETTINGS!$F$24,SETTINGS!$F$31)) -> 0 | BD72: =BC72/$BC$6*50+50 -> 50 | BE72: =BD72*(0.01*IF(D72="lab",SETTINGS!$F$25,"0")) -> 0 | BG72: =BF72/$BF$6*50+50 -> 50 | BH72: =BG72*(0.01*IF(D72="lab",SETTINGS!$F$26,SETTINGS!$F$32)) -> 0 | BI72: =IF(AG72="DRP","DRP",IF(AY72<=40,"FA",BH72+BE72+BB72+AZ72+AX72+AP72)) -> 0
B73: 67 | C73: =SETTINGS!C76 -> 0 | D73: Non-Lab | J73: =SUM(E73:I73) -> 0 | K73: =J73/$J$6*50+50 -> 50 | L73: =K73*(0.01*IF(D73="lab",SETTINGS!$F$22,SETTINGS!$F$29)) -> 0 | R73: =SUM(M73:Q73) -> 0 | S73: =R73/$R$6*50+50 -> 50 | T73: =S73*(0.01*IF(D73="lab",SETTINGS!$F$23,SETTINGS!$F$30)) -> 0 | U73: 100 | V73: =U73*(0.01*IF(D73="lab",SETTINGS!$F$21,SETTINGS!$F$28)) -> 0 | W73: 100 | X73: =W73*(0.01*IF(D73="lab",SETTINGS!$F$24,SETTINGS!$F$31)) -> 0 | Y73: 0 | Z73: =Y73*(0.01*IF(#REF!="ONLINE", SETTINGS!$F$26, IF('MID-FINAL'!#REF!="BLENDED",SETTINGS!$F$34, IF('MID-FINAL'!#REF!="MODULAR",SETTINGS!$F$42)))) -> #REF! | AB73: =AA73/$AA$6*50+50 -> 50 | AC73: =AB73*(0.01*IF(D73="lab",SETTINGS!$F$25,"0")) -> 0 | AE73: =AD73/$AD$6*50+50 -> 50 | AF73: =AE73*(0.01*IF(D73="lab",SETTINGS!$F$26,SETTINGS!$F$32)) -> 0 | AG73: =IF(U73<=40,"DRP",AF73+AC73+X73+V73+T73+L73) -> 0 | AN73: =SUM(AI73:AM73) -> 0 | AO73: =AN73/$AN$6*50+50 -> 50 | AP73: =AO73*(0.01*IF(D73="lab",SETTINGS!$F$22,SETTINGS!$F$29)) -> 0 | AV73: =SUM(AQ73:AU73) -> 0 | AW73: =AV73/$AV$6*50+50 -> 50 | AX73: =AW73*(0.01*IF(D73="lab",SETTINGS!$F$23,SETTINGS!$F$30)) -> 0 | AY73: =ATT!AJ72 -> 100 | AZ73: =AY73*(0.01*IF(D73="lab",SETTINGS!$F$21,SETTINGS!$F$28)) -> 0 | BA73: 100 | BB73: =BA73*(0.01*IF(D73="lab",SETTINGS!$F$24,SETTINGS!$F$31)) -> 0 | BD73: =BC73/$BC$6*50+50 -> 50 | BE73: =BD73*(0.01*IF(D73="lab",SETTINGS!$F$25,"0")) -> 0 | BG73: =BF73/$BF$6*50+50 -> 50 | BH73: =BG73*(0.01*IF(D73="lab",SETTINGS!$F$26,SETTINGS!$F$32)) -> 0 | BI73: =IF(AG73="DRP","DRP",IF(AY73<=40,"FA",BH73+BE73+BB73+AZ73+AX73+AP73)) -> 0
B74: 68 | C74: =SETTINGS!C77 -> 0 | D74: Non-Lab | J74: =SUM(E74:I74) -> 0 | K74: =J74/$J$6*50+50 -> 50 | L74: =K74*(0.01*IF(D74="lab",SETTINGS!$F$22,SETTINGS!$F$29)) -> 0 | R74: =SUM(M74:Q74) -> 0 | S74: =R74/$R$6*50+50 -> 50 | T74: =S74*(0.01*IF(D74="lab",SETTINGS!$F$23,SETTINGS!$F$30)) -> 0 | U74: 100 | V74: =U74*(0.01*IF(D74="lab",SETTINGS!$F$21,SETTINGS!$F$28)) -> 0 | W74: 100 | X74: =W74*(0.01*IF(D74="lab",SETTINGS!$F$24,SETTINGS!$F$31)) -> 0 | Y74: 0 | Z74: =Y74*(0.01*IF(#REF!="ONLINE", SETTINGS!$F$26, IF('MID-FINAL'!#REF!="BLENDED",SETTINGS!$F$34, IF('MID-FINAL'!#REF!="MODULAR",SETTINGS!$F$42)))) -> #REF! | AB74: =AA74/$AA$6*50+50 -> 50 | AC74: =AB74*(0.01*IF(D74="lab",SETTINGS!$F$25,"0")) -> 0 | AE74: =AD74/$AD$6*50+50 -> 50 | AF74: =AE74*(0.01*IF(D74="lab",SETTINGS!$F$26,SETTINGS!$F$32)) -> 0 | AG74: =IF(U74<=40,"DRP",AF74+AC74+X74+V74+T74+L74) -> 0 | AN74: =SUM(AI74:AM74) -> 0 | AO74: =AN74/$AN$6*50+50 -> 50 | AP74: =AO74*(0.01*IF(D74="lab",SETTINGS!$F$22,SETTINGS!$F$29)) -> 0 | AV74: =SUM(AQ74:AU74) -> 0 | AW74: =AV74/$AV$6*50+50 -> 50 | AX74: =AW74*(0.01*IF(D74="lab",SETTINGS!$F$23,SETTINGS!$F$30)) -> 0 | AY74: =ATT!AJ73 -> 100 | AZ74: =AY74*(0.01*IF(D74="lab",SETTINGS!$F$21,SETTINGS!$F$28)) -> 0 | BA74: 100 | BB74: =BA74*(0.01*IF(D74="lab",SETTINGS!$F$24,SETTINGS!$F$31)) -> 0 | BD74: =BC74/$BC$6*50+50 -> 50 | BE74: =BD74*(0.01*IF(D74="lab",SETTINGS!$F$25,"0")) -> 0 | BG74: =BF74/$BF$6*50+50 -> 50 | BH74: =BG74*(0.01*IF(D74="lab",SETTINGS!$F$26,SETTINGS!$F$32)) -> 0 | BI74: =IF(AG74="DRP","DRP",IF(AY74<=40,"FA",BH74+BE74+BB74+AZ74+AX74+AP74)) -> 0
B75: 69 | C75: =SETTINGS!C78 -> 0 | D75: Non-Lab | J75: =SUM(E75:I75) -> 0 | K75: =J75/$J$6*50+50 -> 50 | L75: =K75*(0.01*IF(D75="lab",SETTINGS!$F$22,SETTINGS!$F$29)) -> 0 | R75: =SUM(M75:Q75) -> 0 | S75: =R75/$R$6*50+50 -> 50 | T75: =S75*(0.01*IF(D75="lab",SETTINGS!$F$23,SETTINGS!$F$30)) -> 0 | U75: 100 | V75: =U75*(0.01*IF(D75="lab",SETTINGS!$F$21,SETTINGS!$F$28)) -> 0 | W75: 100 | X75: =W75*(0.01*IF(D75="lab",SETTINGS!$F$24,SETTINGS!$F$31)) -> 0 | Y75: 0 | Z75: =Y75*(0.01*IF(#REF!="ONLINE", SETTINGS!$F$26, IF('MID-FINAL'!#REF!="BLENDED",SETTINGS!$F$34, IF('MID-FINAL'!#REF!="MODULAR",SETTINGS!$F$42)))) -> #REF! | AB75: =AA75/$AA$6*50+50 -> 50 | AC75: =AB75*(0.01*IF(D75="lab",SETTINGS!$F$25,"0")) -> 0 | AE75: =AD75/$AD$6*50+50 -> 50 | AF75: =AE75*(0.01*IF(D75="lab",SETTINGS!$F$26,SETTINGS!$F$32)) -> 0 | AG75: =IF(U75<=40,"DRP",AF75+AC75+X75+V75+T75+L75) -> 0 | AN75: =SUM(AI75:AM75) -> 0 | AO75: =AN75/$AN$6*50+50 -> 50 | AP75: =AO75*(0.01*IF(D75="lab",SETTINGS!$F$22,SETTINGS!$F$29)) -> 0 | AV75: =SUM(AQ75:AU75) -> 0 | AW75: =AV75/$AV$6*50+50 -> 50 | AX75: =AW75*(0.01*IF(D75="lab",SETTINGS!$F$23,SETTINGS!$F$30)) -> 0 | AY75: =ATT!AJ74 -> 100 | AZ75: =AY75*(0.01*IF(D75="lab",SETTINGS!$F$21,SETTINGS!$F$28)) -> 0 | BA75: 100 | BB75: =BA75*(0.01*IF(D75="lab",SETTINGS!$F$24,SETTINGS!$F$31)) -> 0 | BD75: =BC75/$BC$6*50+50 -> 50 | BE75: =BD75*(0.01*IF(D75="lab",SETTINGS!$F$25,"0")) -> 0 | BG75: =BF75/$BF$6*50+50 -> 50 | BH75: =BG75*(0.01*IF(D75="lab",SETTINGS!$F$26,SETTINGS!$F$32)) -> 0 | BI75: =IF(AG75="DRP","DRP",IF(AY75<=40,"FA",BH75+BE75+BB75+AZ75+AX75+AP75)) -> 0
B76: 70 | C76: =SETTINGS!C79 -> 0 | D76: Non-Lab | J76: =SUM(E76:I76) -> 0 | K76: =J76/$J$6*50+50 -> 50 | L76: =K76*(0.01*IF(D76="lab",SETTINGS!$F$22,SETTINGS!$F$29)) -> 0 | R76: =SUM(M76:Q76) -> 0 | S76: =R76/$R$6*50+50 -> 50 | T76: =S76*(0.01*IF(D76="lab",SETTINGS!$F$23,SETTINGS!$F$30)) -> 0 | U76: 100 | V76: =U76*(0.01*IF(D76="lab",SETTINGS!$F$21,SETTINGS!$F$28)) -> 0 | W76: 100 | X76: =W76*(0.01*IF(D76="lab",SETTINGS!$F$24,SETTINGS!$F$31)) -> 0 | Y76: 0 | Z76: =Y76*(0.01*IF(#REF!="ONLINE", SETTINGS!$F$26, IF('MID-FINAL'!#REF!="BLENDED",SETTINGS!$F$34, IF('MID-FINAL'!#REF!="MODULAR",SETTINGS!$F$42)))) -> #REF! | AB76: =AA76/$AA$6*50+50 -> 50 | AC76: =AB76*(0.01*IF(D76="lab",SETTINGS!$F$25,"0")) -> 0 | AE76: =AD76/$AD$6*50+50 -> 50 | AF76: =AE76*(0.01*IF(D76="lab",SETTINGS!$F$26,SETTINGS!$F$32)) -> 0 | AG76: =IF(U76<=40,"DRP",AF76+AC76+X76+V76+T76+L76) -> 0 | AN76: =SUM(AI76:AM76) -> 0 | AO76: =AN76/$AN$6*50+50 -> 50 | AP76: =AO76*(0.01*IF(D76="lab",SETTINGS!$F$22,SETTINGS!$F$29)) -> 0 | AV76: =SUM(AQ76:AU76) -> 0 | AW76: =AV76/$AV$6*50+50 -> 50 | AX76: =AW76*(0.01*IF(D76="lab",SETTINGS!$F$23,SETTINGS!$F$30)) -> 0 | AY76: =ATT!AJ75 -> 100 | AZ76: =AY76*(0.01*IF(D76="lab",SETTINGS!$F$21,SETTINGS!$F$28)) -> 0 | BA76: 100 | BB76: =BA76*(0.01*IF(D76="lab",SETTINGS!$F$24,SETTINGS!$F$31)) -> 0 | BD76: =BC76/$BC$6*50+50 -> 50 | BE76: =BD76*(0.01*IF(D76="lab",SETTINGS!$F$25,"0")) -> 0 | BG76: =BF76/$BF$6*50+50 -> 50 | BH76: =BG76*(0.01*IF(D76="lab",SETTINGS!$F$26,SETTINGS!$F$32)) -> 0 | BI76: =IF(AG76="DRP","DRP",IF(AY76<=40,"FA",BH76+BE76+BB76+AZ76+AX76+AP76)) -> 0
B77: 71 | C77: =SETTINGS!C80 -> 0 | D77: Non-Lab | J77: =SUM(E77:I77) -> 0 | K77: =J77/$J$6*50+50 -> 50 | L77: =K77*(0.01*IF(D77="lab",SETTINGS!$F$22,SETTINGS!$F$29)) -> 0 | R77: =SUM(M77:Q77) -> 0 | S77: =R77/$R$6*50+50 -> 50 | T77: =S77*(0.01*IF(D77="lab",SETTINGS!$F$23,SETTINGS!$F$30)) -> 0 | U77: 100 | V77: =U77*(0.01*IF(D77="lab",SETTINGS!$F$21,SETTINGS!$F$28)) -> 0 | W77: 100 | X77: =W77*(0.01*IF(D77="lab",SETTINGS!$F$24,SETTINGS!$F$31)) -> 0 | Y77: 0 | Z77: =Y77*(0.01*IF(#REF!="ONLINE", SETTINGS!$F$26, IF('MID-FINAL'!#REF!="BLENDED",SETTINGS!$F$34, IF('MID-FINAL'!#REF!="MODULAR",SETTINGS!$F$42)))) -> #REF! | AB77: =AA77/$AA$6*50+50 -> 50 | AC77: =AB77*(0.01*IF(D77="lab",SETTINGS!$F$25,"0")) -> 0 | AE77: =AD77/$AD$6*50+50 -> 50 | AF77: =AE77*(0.01*IF(D77="lab",SETTINGS!$F$26,SETTINGS!$F$32)) -> 0 | AG77: =IF(U77<=40,"DRP",AF77+AC77+X77+V77+T77+L77) -> 0 | AN77: =SUM(AI77:AM77) -> 0 | AO77: =AN77/$AN$6*50+50 -> 50 | AP77: =AO77*(0.01*IF(D77="lab",SETTINGS!$F$22,SETTINGS!$F$29)) -> 0 | AV77: =SUM(AQ77:AU77) -> 0 | AW77: =AV77/$AV$6*50+50 -> 50 | AX77: =AW77*(0.01*IF(D77="lab",SETTINGS!$F$23,SETTINGS!$F$30)) -> 0 | AY77: =ATT!AJ76 -> 100 | AZ77: =AY77*(0.01*IF(D77="lab",SETTINGS!$F$21,SETTINGS!$F$28)) -> 0 | BA77: 100 | BB77: =BA77*(0.01*IF(D77="lab",SETTINGS!$F$24,SETTINGS!$F$31)) -> 0 | BD77: =BC77/$BC$6*50+50 -> 50 | BE77: =BD77*(0.01*IF(D77="lab",SETTINGS!$F$25,"0")) -> 0 | BG77: =BF77/$BF$6*50+50 -> 50 | BH77: =BG77*(0.01*IF(D77="lab",SETTINGS!$F$26,SETTINGS!$F$32)) -> 0 | BI77: =IF(AG77="DRP","DRP",IF(AY77<=40,"FA",BH77+BE77+BB77+AZ77+AX77+AP77)) -> 0
B78: 72 | C78: =SETTINGS!C81 -> 0 | D78: Non-Lab | J78: =SUM(E78:I78) -> 0 | K78: =J78/$J$6*50+50 -> 50 | L78: =K78*(0.01*IF(D78="lab",SETTINGS!$F$22,SETTINGS!$F$29)) -> 0 | R78: =SUM(M78:Q78) -> 0 | S78: =R78/$R$6*50+50 -> 50 | T78: =S78*(0.01*IF(D78="lab",SETTINGS!$F$23,SETTINGS!$F$30)) -> 0 | U78: 100 | V78: =U78*(0.01*IF(D78="lab",SETTINGS!$F$21,SETTINGS!$F$28)) -> 0 | W78: 100 | X78: =W78*(0.01*IF(D78="lab",SETTINGS!$F$24,SETTINGS!$F$31)) -> 0 | Y78: 0 | Z78: =Y78*(0.01*IF(#REF!="ONLINE", SETTINGS!$F$26, IF('MID-FINAL'!#REF!="BLENDED",SETTINGS!$F$34, IF('MID-FINAL'!#REF!="MODULAR",SETTINGS!$F$42)))) -> #REF! | AB78: =AA78/$AA$6*50+50 -> 50 | AC78: =AB78*(0.01*IF(D78="lab",SETTINGS!$F$25,"0")) -> 0 | AE78: =AD78/$AD$6*50+50 -> 50 | AF78: =AE78*(0.01*IF(D78="lab",SETTINGS!$F$26,SETTINGS!$F$32)) -> 0 | AG78: =IF(U78<=40,"DRP",AF78+AC78+X78+V78+T78+L78) -> 0 | AN78: =SUM(AI78:AM78) -> 0 | AO78: =AN78/$AN$6*50+50 -> 50 | AP78: =AO78*(0.01*IF(D78="lab",SETTINGS!$F$22,SETTINGS!$F$29)) -> 0 | AV78: =SUM(AQ78:AU78) -> 0 | AW78: =AV78/$AV$6*50+50 -> 50 | AX78: =AW78*(0.01*IF(D78="lab",SETTINGS!$F$23,SETTINGS!$F$30)) -> 0 | AY78: =ATT!AJ77 -> 100 | AZ78: =AY78*(0.01*IF(D78="lab",SETTINGS!$F$21,SETTINGS!$F$28)) -> 0 | BA78: 100 | BB78: =BA78*(0.01*IF(D78="lab",SETTINGS!$F$24,SETTINGS!$F$31)) -> 0 | BD78: =BC78/$BC$6*50+50 -> 50 | BE78: =BD78*(0.01*IF(D78="lab",SETTINGS!$F$25,"0")) -> 0 | BG78: =BF78/$BF$6*50+50 -> 50 | BH78: =BG78*(0.01*IF(D78="lab",SETTINGS!$F$26,SETTINGS!$F$32)) -> 0 | BI78: =IF(AG78="DRP","DRP",IF(AY78<=40,"FA",BH78+BE78+BB78+AZ78+AX78+AP78)) -> 0
... B82: 76 | C82: =SETTINGS!C85 -> 0 | D82: Non-Lab | J82: =SUM(E82:I82) -> 0 | K82: =J82/$J$6*50+50 -> 50 | L82: =K82*(0.01*IF(D82="lab",SETTINGS!$F$22,SETTINGS!$F$29)) -> 0 | R82: =SUM(M82:Q82) -> 0 | S82: =R82/$R$6*50+50 -> 50 | T82: =S82*(0.01*IF(D82="lab",SETTINGS!$F$23,SETTINGS!$F$30)) -> 0 | U82: 100 | V82: =U82*(0.01*IF(D82="lab",SETTINGS!$F$21,SETTINGS!$F$28)) -> 0 | W82: 100 | X82: =W82*(0.01*IF(D82="lab",SETTINGS!$F$24,SETTINGS!$F$31)) -> 0 | Y82: 0 | Z82: =Y82*(0.01*IF(#REF!="ONLINE", SETTINGS!$F$26, IF('MID-FINAL'!#REF!="BLENDED",SETTINGS!$F$34, IF('MID-FINAL'!#REF!="MODULAR",SETTINGS!$F$42)))) -> #REF! | AB82: =AA82/$AA$6*50+50 -> 50 | AC82: =AB82*(0.01*IF(D82="lab",SETTINGS!$F$25,"0")) -> 0 | AE82: =AD82/$AD$6*50+50 -> 50 | AF82: =AE82*(0.01*IF(D82="lab",SETTINGS!$F$26,SETTINGS!$F$32)) -> 0 | AG82: =IF(U82<=40,"DRP",AF82+AC82+X82+V82+T82+L82) -> 0 | AN82: =SUM(AI82:AM82) -> 0 | AO82: =AN82/$AN$6*50+50 -> 50 | AP82: =AO82*(0.01*IF(D82="lab",SETTINGS!$F$22,SETTINGS!$F$29)) -> 0 | AV82: =SUM(AQ82:AU82) -> 0 | AW82: =AV82/$AV$6*50+50 -> 50 | AX82: =AW82*(0.01*IF(D82="lab",SETTINGS!$F$23,SETTINGS!$F$30)) -> 0 | AY82: =ATT!AJ81 -> 100 | AZ82: =AY82*(0.01*IF(D82="lab",SETTINGS!$F$21,SETTINGS!$F$28)) -> 0 | BA82: 100 | BB82: =BA82*(0.01*IF(D82="lab",SETTINGS!$F$24,SETTINGS!$F$31)) -> 0 | BD82: =BC82/$BC$6*50+50 -> 50 | BE82: =BD82*(0.01*IF(D82="lab",SETTINGS!$F$25,"0")) -> 0 | BG82: =BF82/$BF$6*50+50 -> 50 | BH82: =BG82*(0.01*IF(D82="lab",SETTINGS!$F$26,SETTINGS!$F$32)) -> 0 | BI82: =IF(AG82="DRP","DRP",IF(AY82<=40,"FA",BH82+BE82+BB82+AZ82+AX82+AP82)) -> 0

Sheet AVERAGE
B3: DON HONORIO VENTURA TECHNOLOGICAL STATE UNIVERSITY
B4: STO. TOMAS CAMPUS
B5: Moras dela Paz, Sto. Tomas, Pampanga
B7: =SETTINGS!F10 & " " &SETTINGS!F11 -> Second Semester A.Y. 2023-2024
B9: =SETTINGS!F13 & " - " &SETTINGS!F14 -> -
C11: Class Section: | D11: =SETTINGS!F16 -> 0
B12: No. | C12: Student Number | D12: Student Name | F12: MIDTERM GRADE | I12: INCENTIVES | K12: FINALTERM GRADE | N12: INCENTIVES | P12: FINAL GRADE | S12: REMARKS | V12: INCENTIVES
F13: MTG | G13: 0.5 | I13: POINTS Midterm | K13: FTG | L13: 0.5 | N13: POINTS Finals | P13: FINAL GRADE | Q13: TRANSMUTED | S13: REMARKS | T13: RANKING | V13: POINTS Final Grade
B14: 1 | C14: =SETTINGS!B10 -> 0 | D14: =SETTINGS!C10 -> 0 | F14: =IF('MID-FINAL'!AG7 = "DRP","DRP",'MID-FINAL'!AG7 + I14) -> 0 | G14: =IF(F14="DRP","DRP",IF(F14="FA", "FA",F14*0.5)) -> 0 | I14: 0 | K14: =IF('MID-FINAL'!BI7="DRP","DRP",IF('MID-FINAL'!BI7="FA","FA",'MID-FINAL'!BI7+N14)) -> 0 | L14: =IF(K14="DRP","DRP",IF(K14="FA", "FA",K14*0.5)) -> 0 | N14: 0 | P14: =IF(F14="DRP","DRP",IF(K14="DRP","DRP",IF(F14="FA","FA",IF(K14="FA","FA",ROUND(L14+G14+V14,0))))) -> 0 | Q14: =IF(P14="DRP","DRP",VLOOKUP(P14,'GRADE EQUIVALENTS'!$C$8:$D$109,2,TRUE)) -> #N/A | S14: =IF(Q14=5,"FAILED",IF(Q14="DRP","DROPPED","PASSED")) -> #N/A | T14: =RANK(P14,$P$14:$P$89) -> 1 | V14: 0
B15: 2 | C15: =SETTINGS!B11 -> 0 | D15: =SETTINGS!C11 -> 0 | F15: =IF('MID-FINAL'!AG8 = "DRP","DRP",'MID-FINAL'!AG8 + I15) -> 0 | G15: =IF(F15="DRP","DRP",IF(F15="FA", "FA",F15*0.5)) -> 0 | I15: 0 | K15: =IF('MID-FINAL'!BI8="DRP","DRP",IF('MID-FINAL'!BI8="FA","FA",'MID-FINAL'!BI8+N15)) -> 0 | L15: =IF(K15="DRP","DRP",IF(K15="FA", "FA",K15*0.5)) -> 0 | N15: 0 | P15: =IF(F15="DRP","DRP",IF(K15="DRP","DRP",IF(F15="FA","FA",IF(K15="FA","FA",ROUND(L15+G15+V15,0))))) -> 0 | Q15: =IF(P15="DRP","DRP",VLOOKUP(P15,'GRADE EQUIVALENTS'!$C$8:$D$109,2,TRUE)) -> #N/A | S15: =IF(Q15=5,"FAILED",IF(Q15="DRP","DROPPED","PASSED")) -> #N/A | T15: =RANK(P15,$P$14:$P$89) -> 1 | V15: 0
B16: 3 | C16: =SETTINGS!B12 -> 0 | D16: =SETTINGS!C12 -> 0 | F16: =IF('MID-FINAL'!AG9 = "DRP","DRP",'MID-FINAL'!AG9 + I16) -> 0 | G16: =IF(F16="DRP","DRP",IF(F16="FA", "FA",F16*0.5)) -> 0 | I16: 0 | K16: =IF('MID-FINAL'!BI9="DRP","DRP",IF('MID-FINAL'!BI9="FA","FA",'MID-FINAL'!BI9+N16)) -> 0 | L16: =IF(K16="DRP","DRP",IF(K16="FA", "FA",K16*0.5)) -> 0 | N16: 0 | P16: =IF(F16="DRP","DRP",IF(K16="DRP","DRP",IF(F16="FA","FA",IF(K16="FA","FA",ROUND(L16+G16+V16,0))))) -> 0 | Q16: =IF(P16="DRP","DRP",VLOOKUP(P16,'GRADE EQUIVALENTS'!$C$8:$D$109,2,TRUE)) -> #N/A | S16: =IF(Q16=5,"FAILED",IF(Q16="DRP","DROPPED","PASSED")) -> #N/A | T16: =RANK(P16,$P$14:$P$89) -> 1 | V16: 0
B17: 4 | C17: =SETTINGS!B13 -> 0 | D17: =SETTINGS!C13 -> 0 | F17: =IF('MID-FINAL'!AG10 = "DRP","DRP",'MID-FINAL'!AG10 + I17) -> 0 | G17: =IF(F17="DRP","DRP",IF(F17="FA", "FA",F17*0.5)) -> 0 | I17: 0 | K17: =IF('MID-FINAL'!BI10="DRP","DRP",IF('MID-FINAL'!BI10="FA","FA",'MID-FINAL'!BI10+N17)) -> 0 | L17: =IF(K17="DRP","DRP",IF(K17="FA", "FA",K17*0.5)) -> 0 | N17: 0 | P17: =IF(F17="DRP","DRP",IF(K17="DRP","DRP",IF(F17="FA","FA",IF(K17="FA","FA",ROUND(L17+G17+V17,0))))) -> 0 | Q17: =IF(P17="DRP","DRP",VLOOKUP(P17,'GRADE EQUIVALENTS'!$C$8:$D$109,2,TRUE)) -> #N/A | S17: =IF(Q17=5,"FAILED",IF(Q17="DRP","DROPPED","PASSED")) -> #N/A | T17: =RANK(P17,$P$14:$P$89) -> 1 | V17: 0
B18: 5 | C18: =SETTINGS!B14 -> 0 | D18: =SETTINGS!C14 -> 0 | F18: =IF('MID-FINAL'!AG11 = "DRP","DRP",'MID-FINAL'!AG11 + I18) -> 0 | G18: =IF(F18="DRP","DRP",IF(F18="FA", "FA",F18*0.5)) -> 0 | I18: 0 | K18: =IF('MID-FINAL'!BI11="DRP","DRP",IF('MID-FINAL'!BI11="FA","FA",'MID-FINAL'!BI11+N18)) -> 0 | L18: =IF(K18="DRP","DRP",IF(K18="FA", "FA",K18*0.5)) -> 0 | N18: 0 | P18: =IF(F18="DRP","DRP",IF(K18="DRP","DRP",IF(F18="FA","FA",IF(K18="FA","FA",ROUND(L18+G18+V18,0))))) -> 0 | Q18: =IF(P18="DRP","DRP",VLOOKUP(P18,'GRADE EQUIVALENTS'!$C$8:$D$109,2,TRUE)) -> #N/A | S18: =IF(Q18=5,"FAILED",IF(Q18="DRP","DROPPED","PASSED")) -> #N/A | T18: =RANK(P18,$P$14:$P$89) -> 1 | V18: 0
B19: 6 | C19: =SETTINGS!B15 -> 0 | D19: =SETTINGS!C15 -> 0 | F19: =IF('MID-FINAL'!AG12 = "DRP","DRP",'MID-FINAL'!AG12 + I19) -> 0 | G19: =IF(F19="DRP","DRP",IF(F19="FA", "FA",F19*0.5)) -> 0 | I19: 0 | K19: =IF('MID-FINAL'!BI12="DRP","DRP",IF('MID-FINAL'!BI12="FA","FA",'MID-FINAL'!BI12+N19)) -> 0 | L19: =IF(K19="DRP","DRP",IF(K19="FA", "FA",K19*0.5)) -> 0 | N19: 0 | P19: =IF(F19="DRP","DRP",IF(K19="DRP","DRP",IF(F19="FA","FA",IF(K19="FA","FA",ROUND(L19+G19+V19,0))))) -> 0 | Q19: =IF(P19="DRP","DRP",VLOOKUP(P19,'GRADE EQUIVALENTS'!$C$8:$D$109,2,TRUE)) -> #N/A | S19: =IF(Q19=5,"FAILED",IF(Q19="DRP","DROPPED","PASSED")) -> #N/A | T19: =RANK(P19,$P$14:$P$89) -> 1 | V19: 0
B20: 7 | C20: =SETTINGS!B16 -> 0 | D20: =SETTINGS!C16 -> 0 | F20: =IF('MID-FINAL'!AG13 = "DRP","DRP",'MID-FINAL'!AG13 + I20) -> 0 | G20: =IF(F20="DRP","DRP",IF(F20="FA", "FA",F20*0.5)) -> 0 | I20: 0 | K20: =IF('MID-FINAL'!BI13="DRP","DRP",IF('MID-FINAL'!BI13="FA","FA",'MID-FINAL'!BI13+N20)) -> 0 | L20: =IF(K20="DRP","DRP",IF(K20="FA", "FA",K20*0.5)) -> 0 | N20: 0 | P20: =IF(F20="DRP","DRP",IF(K20="DRP","DRP",IF(F20="FA","FA",IF(K20="FA","FA",ROUND(L20+G20+V20,0))))) -> 0 | Q20: =IF(P20="DRP","DRP",VLOOKUP(P20,'GRADE EQUIVALENTS'!$C$8:$D$109,2,TRUE)) -> #N/A | S20: =IF(Q20=5,"FAILED",IF(Q20="DRP","DROPPED","PASSED")) -> #N/A | T20: =RANK(P20,$P$14:$P$89) -> 1 | V20: 0
B21: 8 | C21: =SETTINGS!B17 -> 0 | D21: =SETTINGS!C17 -> 0 | F21: =IF('MID-FINAL'!AG14 = "DRP","DRP",'MID-FINAL'!AG14 + I21) -> 0 | G21: =IF(F21="DRP","DRP",IF(F21="FA", "FA",F21*0.5)) -> 0 | I21: 0 | K21: =IF('MID-FINAL'!BI14="DRP","DRP",IF('MID-FINAL'!BI14="FA","FA",'MID-FINAL'!BI14+N21)) -> 0 | L21: =IF(K21="DRP","DRP",IF(K21="FA", "FA",K21*0.5)) -> 0 | N21: 0 | P21: =IF(F21="DRP","DRP",IF(K21="DRP","DRP",IF(F21="FA","FA",IF(K21="FA","FA",ROUND(L21+G21+V21,0))))) -> 0 | Q21: =IF(P21="DRP","DRP",VLOOKUP(P21,'GRADE EQUIVALENTS'!$C$8:$D$109,2,TRUE)) -> #N/A | S21: =IF(Q21=5,"FAILED",IF(Q21="DRP","DROPPED","PASSED")) -> #N/A | T21: =RANK(P21,$P$14:$P$89) -> 1 | V21: 0
B22: 9 | C22: =SETTINGS!B18 -> 0 | D22: =SETTINGS!C18 -> 0 | F22: =IF('MID-FINAL'!AG15 = "DRP","DRP",'MID-FINAL'!AG15 + I22) -> 0 | G22: =IF(F22="DRP","DRP",IF(F22="FA", "FA",F22*0.5)) -> 0 | I22: 0 | K22: =IF('MID-FINAL'!BI15="DRP","DRP",IF('MID-FINAL'!BI15="FA","FA",'MID-FINAL'!BI15+N22)) -> 0 | L22: =IF(K22="DRP","DRP",IF(K22="FA", "FA",K22*0.5)) -> 0 | N22: 0 | P22: =IF(F22="DRP","DRP",IF(K22="DRP","DRP",IF(F22="FA","FA",IF(K22="FA","FA",ROUND(L22+G22+V22,0))))) -> 0 | Q22: =IF(P22="DRP","DRP",VLOOKUP(P22,'GRADE EQUIVALENTS'!$C$8:$D$109,2,TRUE)) -> #N/A | S22: =IF(Q22=5,"FAILED",IF(Q22="DRP","DROPPED","PASSED")) -> #N/A | T22: =RANK(P22,$P$14:$P$89) -> 1 | V22: 0
B23: 10 | C23: =SETTINGS!B19 -> 0 | D23: =SETTINGS!C19 -> 0 | F23: =IF('MID-FINAL'!AG16 = "DRP","DRP",'MID-FINAL'!AG16 + I23) -> 0 | G23: =IF(F23="DRP","DRP",IF(F23="FA", "FA",F23*0.5)) -> 0 | I23: 0 | K23: =IF('MID-FINAL'!BI16="DRP","DRP",IF('MID-FINAL'!BI16="FA","FA",'MID-FINAL'!BI16+N23)) -> 0 | L23: =IF(K23="DRP","DRP",IF(K23="FA", "FA",K23*0.5)) -> 0 | N23: 0 | P23: =IF(F23="DRP","DRP",IF(K23="DRP","DRP",IF(F23="FA","FA",IF(K23="FA","FA",ROUND(L23+G23+V23,0))))) -> 0 | Q23: =IF(P23="DRP","DRP",VLOOKUP(P23,'GRADE EQUIVALENTS'!$C$8:$D$109,2,TRUE)) -> #N/A | S23: =IF(Q23=5,"FAILED",IF(Q23="DRP","DROPPED","PASSED")) -> #N/A | T23: =RANK(P23,$P$14:$P$89) -> 1 | V23: 0
B24: 11 | C24: =SETTINGS!B20 -> 0 | D24: =SETTINGS!C20 -> 0 | F24: =IF('MID-FINAL'!AG17 = "DRP","DRP",'MID-FINAL'!AG17 + I24) -> 0 | G24: =IF(F24="DRP","DRP",IF(F24="FA", "FA",F24*0.5)) -> 0 | I24: 0 | K24: =IF('MID-FINAL'!BI17="DRP","DRP",IF('MID-FINAL'!BI17="FA","FA",'MID-FINAL'!BI17+N24)) -> 0 | L24: =IF(K24="DRP","DRP",IF(K24="FA", "FA",K24*0.5)) -> 0 | N24: 0 | P24: =IF(F24="DRP","DRP",IF(K24="DRP","DRP",IF(F24="FA","FA",IF(K24="FA","FA",ROUND(L24+G24+V24,0))))) -> 0 | Q24: =IF(P24="DRP","DRP",VLOOKUP(P24,'GRADE EQUIVALENTS'!$C$8:$D$109,2,TRUE)) -> #N/A | S24: =IF(Q24=5,"FAILED",IF(Q24="DRP","DROPPED","PASSED")) -> #N/A | T24: =RANK(P24,$P$14:$P$89) -> 1 | V24: 0
B25: 12 | C25: =SETTINGS!B21 -> 0 | D25: =SETTINGS!C21 -> 0 | F25: =IF('MID-FINAL'!AG18 = "DRP","DRP",'MID-FINAL'!AG18 + I25) -> 0 | G25: =IF(F25="DRP","DRP",IF(F25="FA", "FA",F25*0.5)) -> 0 | I25: 0 | K25: =IF('MID-FINAL'!BI18="DRP","DRP",IF('MID-FINAL'!BI18="FA","FA",'MID-FINAL'!BI18+N25)) -> 0 | L25: =IF(K25="DRP","DRP",IF(K25="FA", "FA",K25*0.5)) -> 0 | N25: 0 | P25: =IF(F25="DRP","DRP",IF(K25="DRP","DRP",IF(F25="FA","FA",IF(K25="FA","FA",ROUND(L25+G25+V25,0))))) -> 0 | Q25: =IF(P25="DRP","DRP",VLOOKUP(P25,'GRADE EQUIVALENTS'!$C$8:$D$109,2,TRUE)) -> #N/A | S25: =IF(Q25=5,"FAILED",IF(Q25="DRP","DROPPED","PASSED")) -> #N/A | T25: =RANK(P25,$P$14:$P$89) -> 1 | V25: 0
... B89: 76 | C89: =SETTINGS!B85 -> 0 | D89: =SETTINGS!C85 -> 0 | F89: =IF('MID-FINAL'!AG82 = "DRP","DRP",'MID-FINAL'!AG82 + I89) -> 0 | G89: =IF(F89="DRP","DRP",IF(F89="FA", "FA",F89*0.5)) -> 0 | I89: 0 | K89: =IF('MID-FINAL'!BI82="DRP","DRP",IF('MID-FINAL'!BI82="FA","FA",'MID-FINAL'!BI82+N89)) -> 0 | L89: =IF(K89="DRP","DRP",IF(K89="FA", "FA",K89*0.5)) -> 0 | N89: 0 | P89: =IF(F89="DRP","DRP",IF(K89="DRP","DRP",IF(F89="FA","FA",IF(K89="FA","FA",ROUND(L89+G89+V89,0))))) -> 0 | Q89: =IF(P89="DRP","DRP",VLOOKUP(P89,'GRADE EQUIVALENTS'!$C$8:$D$109,2,TRUE)) -> #N/A | S89: =IF(Q89=5,"FAILED",IF(Q89="DRP","DROPPED","PASSED")) -> #N/A | T89: =RANK(P89,$P$14:$P$89) -> 1 | V89: 0

Sheet GRADE EQUIVALENTS
B4: GRADE EQUIVALENTS
C8: 1 | D8: 5
C9: 2 | D9: 5
C10: 3 | D10: 5
C11: 4 | D11: 5
C12: 5 | D12: 5
C13: 6 | D13: 5
C14: 7 | D14: 5
C15: 8 | D15: 5
C16: 9 | D16: 5
C17: 10 | D17: 5
C18: 11 | D18: 5
C19: 12 | D19: 5
... C107: 100 | D107: 1
C108: FA | D108: 5
C109: DRP | D109: 5

Sheet MIDTERM SOG
A2: Commision on Higher Education
A3: DON HONORIO VENTURA TECHNOLOGICAL STATE UNIVERSITY
A4: Sto. Tomas Campus
A6: =SETTINGS!F13 & " - " & SETTINGS!F14 -> -
A7: =SETTINGS!F10 & " " &SETTINGS!F11 -> Second Semester A.Y. 2023-2024
A9: SUMMARY OF GRADES (MIDTERM)
B10: ="Section: " & SETTINGS!F16 -> Section:
B11: No. | C11: Name | D11: Attendance | H11: Grade | I11: Remarks | K11: No. | L11: Name | M11: Attendance | Q11: Grade | R11: Remarks
D12: P | E12: A | F12: L | G12: Total | M12: P | N12: A | O12: L | P12: Total
B13: 1 | C13: =SETTINGS!C10 -> 0 | D13: =COUNTBLANK(ATT!D6:R6)-COUNTBLANK(ATT!$D$2:$R$2) -> 3 | E13: =COUNTIFS(ATT!D6:R6,"="&10) -> 0 | F13: =COUNTIFS(ATT!D6:R6,"="&5) -> 0 | G13: =COUNTA(ATT!$D$2:$R$5) -> 3 | H13: =IF(AVERAGE!F14="DRP","DRP",VLOOKUP(AVERAGE!F14,'GRADE EQUIVALENTS'!$C$8:$D$109,2,TRUE)) -> #N/A | I13: =IF(H13=5,"FAILED",IF(H13="FA","FAILED",IF(H13="DRP","DROPPED","PASSED"))) -> #N/A | K13: 51 | L13: =SETTINGS!C60 -> 0 | M13: =COUNTBLANK(ATT!D56:R56)-COUNTBLANK(ATT!$D$2:$R$2) -> 3 | N13: =COUNTIFS(ATT!D56:R56,"="&10) -> 0 | O13: =COUNTIFS(ATT!D56:R56,"="&5) -> 0 | P13: =COUNTA(ATT!$D$2:$R$5) -> 3 | Q13: =IF(AVERAGE!F64="DRP","DRP",VLOOKUP(AVERAGE!F64,'GRADE EQUIVALENTS'!$C$8:$D$109,2,TRUE)) -> #N/A | R13: =IF(Q13=5,"FAILED",IF(Q13="FA","FAILED",IF(Q13="DRP","DROPPED","PASSED"))) -> #N/A
B14: 2 | C14: =SETTINGS!C11 -> 0 | D14: =COUNTBLANK(ATT!D7:R7)-COUNTBLANK(ATT!$D$2:$R$2) -> 3 | E14: =COUNTIFS(ATT!D7:R7,"="&10) -> 0 | F14: =COUNTIFS(ATT!D7:R7,"="&5) -> 0 | G14: =COUNTA(ATT!$D$2:$R$5) -> 3 | H14: =IF(AVERAGE!F15="DRP","DRP",VLOOKUP(AVERAGE!F15,'GRADE EQUIVALENTS'!$C$8:$D$109,2,TRUE)) -> #N/A | I14: =IF(H14=5,"FAILED",IF(H14="FA","FAILED",IF(H14="DRP","DROPPED","PASSED"))) -> #N/A | K14: 52 | L14: =SETTINGS!C61 -> 0 | M14: =COUNTBLANK(ATT!D57:R57)-COUNTBLANK(ATT!$D$2:$R$2) -> 3 | N14: =COUNTIFS(ATT!D57:R57,"="&10) -> 0 | O14: =COUNTIFS(ATT!D57:R57,"="&5) -> 0 | P14: =COUNTA(ATT!$D$2:$R$5) -> 3 | Q14: =IF(AVERAGE!F65="DRP","DRP",VLOOKUP(AVERAGE!F65,'GRADE EQUIVALENTS'!$C$8:$D$109,2,TRUE)) -> #N/A | R14: =IF(Q14=5,"FAILED",IF(Q14="FA","FAILED",IF(Q14="DRP","DROPPED","PASSED"))) -> #N/A
B15: 3 | C15: =SETTINGS!C12 -> 0 | D15: =COUNTBLANK(ATT!D8:R8)-COUNTBLANK(ATT!$D$2:$R$2) -> 3 | E15: =COUNTIFS(ATT!D8:R8,"="&10) -> 0 | F15: =COUNTIFS(ATT!D8:R8,"="&5) -> 0 | G15: =COUNTA(ATT!$D$2:$R$5) -> 3 | H15: =IF(AVERAGE!F16="DRP","DRP",VLOOKUP(AVERAGE!F16,'GRADE EQUIVALENTS'!$C$8:$D$109,2,TRUE)) -> #N/A | I15: =IF(H15=5,"FAILED",IF(H15="FA","FAILED",IF(H15="DRP","DROPPED","PASSED"))) -> #N/A | K15: 53 | L15: =SETTINGS!C62 -> 0 | M15: =COUNTBLANK(ATT!D58:R58)-COUNTBLANK(ATT!$D$2:$R$2) -> 3 | N15: =COUNTIFS(ATT!D58:R58,"="&10) -> 0 | O15: =COUNTIFS(ATT!D58:R58,"="&5) -> 0 | P15: =COUNTA(ATT!$D$2:$R$5) -> 3 | Q15: =IF(AVERAGE!F66="DRP","DRP",VLOOKUP(AVERAGE!F66,'GRADE EQUIVALENTS'!$C$8:$D$109,2,TRUE)) -> #N/A | R15: =IF(Q15=5,"FAILED",IF(Q15="FA","FAILED",IF(Q15="DRP","DROPPED","PASSED"))) -> #N/A
B16: 4 | C16: =SETTINGS!C13 -> 0 | D16: =COUNTBLANK(ATT!D9:R9)-COUNTBLANK(ATT!$D$2:$R$2) -> 3 | E16: =COUNTIFS(ATT!D9:R9,"="&10) -> 0 | F16: =COUNTIFS(ATT!D9:R9,"="&5) -> 0 | G16: =COUNTA(ATT!$D$2:$R$5) -> 3 | H16: =IF(AVERAGE!F17="DRP","DRP",VLOOKUP(AVERAGE!F17,'GRADE EQUIVALENTS'!$C$8:$D$109,2,TRUE)) -> #N/A | I16: =IF(H16=5,"FAILED",IF(H16="FA","FAILED",IF(H16="DRP","DROPPED","PASSED"))) -> #N/A | K16: 54 | L16: =SETTINGS!C63 -> 0 | M16: =COUNTBLANK(ATT!D59:R59)-COUNTBLANK(ATT!$D$2:$R$2) -> 3 | N16: =COUNTIFS(ATT!D59:R59,"="&10) -> 0 | O16: =COUNTIFS(ATT!D59:R59,"="&5) -> 0 | P16: =COUNTA(ATT!$D$2:$R$5) -> 3 | Q16: =IF(AVERAGE!F67="DRP","DRP",VLOOKUP(AVERAGE!F67,'GRADE EQUIVALENTS'!$C$8:$D$109,2,TRUE)) -> #N/A | R16: =IF(Q16=5,"FAILED",IF(Q16="FA","FAILED",IF(Q16="DRP","DROPPED","PASSED"))) -> #N/A
